[2020-06-01 14:51:11,568] {scheduler_job.py:153} INFO - Started process (PID=456) to work on /usr/local/lib/python3.8/dist-packages/airflow/example_dags/example_trigger_target_dag.py
[2020-06-01 14:51:11,573] {scheduler_job.py:1562} INFO - Processing file /usr/local/lib/python3.8/dist-packages/airflow/example_dags/example_trigger_target_dag.py for tasks to queue
[2020-06-01 14:51:11,574] {logging_mixin.py:112} INFO - [2020-06-01 14:51:11,574] {dagbag.py:396} INFO - Filling up the DagBag from /usr/local/lib/python3.8/dist-packages/airflow/example_dags/example_trigger_target_dag.py
[2020-06-01 14:51:11,632] {scheduler_job.py:1574} INFO - DAG(s) dict_keys(['example_trigger_target_dag']) retrieved from /usr/local/lib/python3.8/dist-packages/airflow/example_dags/example_trigger_target_dag.py
[2020-06-01 14:51:11,831] {scheduler_job.py:166} ERROR - Got an exception! Propagating...
Traceback (most recent call last):
  File "/usr/local/lib/python3.8/dist-packages/sqlalchemy/engine/base.py", line 774, in _commit_impl
    self.engine.dialect.do_commit(self.connection)
  File "/usr/local/lib/python3.8/dist-packages/sqlalchemy/engine/default.py", line 543, in do_commit
    dbapi_connection.commit()
sqlite3.OperationalError: disk I/O error

The above exception was the direct cause of the following exception:

Traceback (most recent call last):
  File "/usr/local/lib/python3.8/dist-packages/airflow/jobs/scheduler_job.py", line 156, in _run_file_processor
    result = scheduler_job.process_file(file_path,
  File "/usr/local/lib/python3.8/dist-packages/airflow/utils/db.py", line 74, in wrapper
    return func(*args, **kwargs)
  File "/usr/local/lib/python3.8/dist-packages/airflow/jobs/scheduler_job.py", line 1582, in process_file
    dag.sync_to_db()
  File "/usr/local/lib/python3.8/dist-packages/airflow/utils/db.py", line 74, in wrapper
    return func(*args, **kwargs)
  File "/usr/local/lib/python3.8/dist-packages/airflow/models/dag.py", line 1516, in sync_to_db
    orm_dag.tags = self.get_dagtags(session=session)
  File "/usr/local/lib/python3.8/dist-packages/airflow/utils/db.py", line 70, in wrapper
    return func(*args, **kwargs)
  File "/usr/local/lib/python3.8/dist-packages/airflow/models/dag.py", line 1555, in get_dagtags
    session.commit()
  File "/usr/local/lib/python3.8/dist-packages/sqlalchemy/orm/session.py", line 1042, in commit
    self.transaction.commit()
  File "/usr/local/lib/python3.8/dist-packages/sqlalchemy/orm/session.py", line 508, in commit
    t[1].commit()
  File "/usr/local/lib/python3.8/dist-packages/sqlalchemy/engine/base.py", line 1771, in commit
    self._do_commit()
  File "/usr/local/lib/python3.8/dist-packages/sqlalchemy/engine/base.py", line 1802, in _do_commit
    self.connection._commit_impl()
  File "/usr/local/lib/python3.8/dist-packages/sqlalchemy/engine/base.py", line 776, in _commit_impl
    self._handle_dbapi_exception(e, None, None, None, None)
  File "/usr/local/lib/python3.8/dist-packages/sqlalchemy/engine/base.py", line 1517, in _handle_dbapi_exception
    util.raise_(
  File "/usr/local/lib/python3.8/dist-packages/sqlalchemy/util/compat.py", line 178, in raise_
    raise exception
  File "/usr/local/lib/python3.8/dist-packages/sqlalchemy/engine/base.py", line 774, in _commit_impl
    self.engine.dialect.do_commit(self.connection)
  File "/usr/local/lib/python3.8/dist-packages/sqlalchemy/engine/default.py", line 543, in do_commit
    dbapi_connection.commit()
sqlalchemy.exc.OperationalError: (sqlite3.OperationalError) disk I/O error
(Background on this error at: http://sqlalche.me/e/e3q8)
[2020-06-01 14:53:11,390] {scheduler_job.py:153} INFO - Started process (PID=524) to work on /usr/local/lib/python3.8/dist-packages/airflow/example_dags/example_trigger_target_dag.py
[2020-06-01 14:53:11,407] {scheduler_job.py:1562} INFO - Processing file /usr/local/lib/python3.8/dist-packages/airflow/example_dags/example_trigger_target_dag.py for tasks to queue
[2020-06-01 14:53:11,409] {logging_mixin.py:112} INFO - [2020-06-01 14:53:11,409] {dagbag.py:396} INFO - Filling up the DagBag from /usr/local/lib/python3.8/dist-packages/airflow/example_dags/example_trigger_target_dag.py
[2020-06-01 14:53:11,436] {scheduler_job.py:1574} INFO - DAG(s) dict_keys(['example_trigger_target_dag']) retrieved from /usr/local/lib/python3.8/dist-packages/airflow/example_dags/example_trigger_target_dag.py
[2020-06-01 14:53:11,633] {scheduler_job.py:161} INFO - Processing /usr/local/lib/python3.8/dist-packages/airflow/example_dags/example_trigger_target_dag.py took 0.243 seconds
[2020-06-01 14:53:59,453] {scheduler_job.py:153} INFO - Started process (PID=591) to work on /usr/local/lib/python3.8/dist-packages/airflow/example_dags/example_trigger_target_dag.py
[2020-06-01 14:53:59,459] {scheduler_job.py:1562} INFO - Processing file /usr/local/lib/python3.8/dist-packages/airflow/example_dags/example_trigger_target_dag.py for tasks to queue
[2020-06-01 14:53:59,460] {logging_mixin.py:112} INFO - [2020-06-01 14:53:59,460] {dagbag.py:396} INFO - Filling up the DagBag from /usr/local/lib/python3.8/dist-packages/airflow/example_dags/example_trigger_target_dag.py
[2020-06-01 14:53:59,471] {scheduler_job.py:1574} INFO - DAG(s) dict_keys(['example_trigger_target_dag']) retrieved from /usr/local/lib/python3.8/dist-packages/airflow/example_dags/example_trigger_target_dag.py
[2020-06-01 14:53:59,654] {scheduler_job.py:166} ERROR - Got an exception! Propagating...
Traceback (most recent call last):
  File "/usr/local/lib/python3.8/dist-packages/sqlalchemy/engine/base.py", line 774, in _commit_impl
    self.engine.dialect.do_commit(self.connection)
  File "/usr/local/lib/python3.8/dist-packages/sqlalchemy/engine/default.py", line 543, in do_commit
    dbapi_connection.commit()
sqlite3.OperationalError: disk I/O error

The above exception was the direct cause of the following exception:

Traceback (most recent call last):
  File "/usr/local/lib/python3.8/dist-packages/airflow/jobs/scheduler_job.py", line 156, in _run_file_processor
    result = scheduler_job.process_file(file_path,
  File "/usr/local/lib/python3.8/dist-packages/airflow/utils/db.py", line 74, in wrapper
    return func(*args, **kwargs)
  File "/usr/local/lib/python3.8/dist-packages/airflow/jobs/scheduler_job.py", line 1582, in process_file
    dag.sync_to_db()
  File "/usr/local/lib/python3.8/dist-packages/airflow/utils/db.py", line 74, in wrapper
    return func(*args, **kwargs)
  File "/usr/local/lib/python3.8/dist-packages/airflow/models/dag.py", line 1516, in sync_to_db
    orm_dag.tags = self.get_dagtags(session=session)
  File "/usr/local/lib/python3.8/dist-packages/airflow/utils/db.py", line 70, in wrapper
    return func(*args, **kwargs)
  File "/usr/local/lib/python3.8/dist-packages/airflow/models/dag.py", line 1555, in get_dagtags
    session.commit()
  File "/usr/local/lib/python3.8/dist-packages/sqlalchemy/orm/session.py", line 1042, in commit
    self.transaction.commit()
  File "/usr/local/lib/python3.8/dist-packages/sqlalchemy/orm/session.py", line 508, in commit
    t[1].commit()
  File "/usr/local/lib/python3.8/dist-packages/sqlalchemy/engine/base.py", line 1771, in commit
    self._do_commit()
  File "/usr/local/lib/python3.8/dist-packages/sqlalchemy/engine/base.py", line 1802, in _do_commit
    self.connection._commit_impl()
  File "/usr/local/lib/python3.8/dist-packages/sqlalchemy/engine/base.py", line 776, in _commit_impl
    self._handle_dbapi_exception(e, None, None, None, None)
  File "/usr/local/lib/python3.8/dist-packages/sqlalchemy/engine/base.py", line 1517, in _handle_dbapi_exception
    util.raise_(
  File "/usr/local/lib/python3.8/dist-packages/sqlalchemy/util/compat.py", line 178, in raise_
    raise exception
  File "/usr/local/lib/python3.8/dist-packages/sqlalchemy/engine/base.py", line 774, in _commit_impl
    self.engine.dialect.do_commit(self.connection)
  File "/usr/local/lib/python3.8/dist-packages/sqlalchemy/engine/default.py", line 543, in do_commit
    dbapi_connection.commit()
sqlalchemy.exc.OperationalError: (sqlite3.OperationalError) disk I/O error
(Background on this error at: http://sqlalche.me/e/e3q8)
[2020-06-01 14:54:47,497] {scheduler_job.py:153} INFO - Started process (PID=619) to work on /usr/local/lib/python3.8/dist-packages/airflow/example_dags/example_trigger_target_dag.py
[2020-06-01 14:54:47,502] {scheduler_job.py:1562} INFO - Processing file /usr/local/lib/python3.8/dist-packages/airflow/example_dags/example_trigger_target_dag.py for tasks to queue
[2020-06-01 14:54:47,502] {logging_mixin.py:112} INFO - [2020-06-01 14:54:47,502] {dagbag.py:396} INFO - Filling up the DagBag from /usr/local/lib/python3.8/dist-packages/airflow/example_dags/example_trigger_target_dag.py
[2020-06-01 14:54:47,512] {scheduler_job.py:1574} INFO - DAG(s) dict_keys(['example_trigger_target_dag']) retrieved from /usr/local/lib/python3.8/dist-packages/airflow/example_dags/example_trigger_target_dag.py
[2020-06-01 14:54:47,684] {scheduler_job.py:166} ERROR - Got an exception! Propagating...
Traceback (most recent call last):
  File "/usr/local/lib/python3.8/dist-packages/sqlalchemy/engine/base.py", line 774, in _commit_impl
    self.engine.dialect.do_commit(self.connection)
  File "/usr/local/lib/python3.8/dist-packages/sqlalchemy/engine/default.py", line 543, in do_commit
    dbapi_connection.commit()
sqlite3.OperationalError: disk I/O error

The above exception was the direct cause of the following exception:

Traceback (most recent call last):
  File "/usr/local/lib/python3.8/dist-packages/airflow/jobs/scheduler_job.py", line 156, in _run_file_processor
    result = scheduler_job.process_file(file_path,
  File "/usr/local/lib/python3.8/dist-packages/airflow/utils/db.py", line 74, in wrapper
    return func(*args, **kwargs)
  File "/usr/local/lib/python3.8/dist-packages/airflow/jobs/scheduler_job.py", line 1582, in process_file
    dag.sync_to_db()
  File "/usr/local/lib/python3.8/dist-packages/airflow/utils/db.py", line 74, in wrapper
    return func(*args, **kwargs)
  File "/usr/local/lib/python3.8/dist-packages/airflow/models/dag.py", line 1516, in sync_to_db
    orm_dag.tags = self.get_dagtags(session=session)
  File "/usr/local/lib/python3.8/dist-packages/airflow/utils/db.py", line 70, in wrapper
    return func(*args, **kwargs)
  File "/usr/local/lib/python3.8/dist-packages/airflow/models/dag.py", line 1555, in get_dagtags
    session.commit()
  File "/usr/local/lib/python3.8/dist-packages/sqlalchemy/orm/session.py", line 1042, in commit
    self.transaction.commit()
  File "/usr/local/lib/python3.8/dist-packages/sqlalchemy/orm/session.py", line 508, in commit
    t[1].commit()
  File "/usr/local/lib/python3.8/dist-packages/sqlalchemy/engine/base.py", line 1771, in commit
    self._do_commit()
  File "/usr/local/lib/python3.8/dist-packages/sqlalchemy/engine/base.py", line 1802, in _do_commit
    self.connection._commit_impl()
  File "/usr/local/lib/python3.8/dist-packages/sqlalchemy/engine/base.py", line 776, in _commit_impl
    self._handle_dbapi_exception(e, None, None, None, None)
  File "/usr/local/lib/python3.8/dist-packages/sqlalchemy/engine/base.py", line 1517, in _handle_dbapi_exception
    util.raise_(
  File "/usr/local/lib/python3.8/dist-packages/sqlalchemy/util/compat.py", line 178, in raise_
    raise exception
  File "/usr/local/lib/python3.8/dist-packages/sqlalchemy/engine/base.py", line 774, in _commit_impl
    self.engine.dialect.do_commit(self.connection)
  File "/usr/local/lib/python3.8/dist-packages/sqlalchemy/engine/default.py", line 543, in do_commit
    dbapi_connection.commit()
sqlalchemy.exc.OperationalError: (sqlite3.OperationalError) disk I/O error
(Background on this error at: http://sqlalche.me/e/e3q8)
[2020-06-01 14:55:35,601] {scheduler_job.py:153} INFO - Started process (PID=651) to work on /usr/local/lib/python3.8/dist-packages/airflow/example_dags/example_trigger_target_dag.py
[2020-06-01 14:55:35,606] {scheduler_job.py:1562} INFO - Processing file /usr/local/lib/python3.8/dist-packages/airflow/example_dags/example_trigger_target_dag.py for tasks to queue
[2020-06-01 14:55:35,607] {logging_mixin.py:112} INFO - [2020-06-01 14:55:35,607] {dagbag.py:396} INFO - Filling up the DagBag from /usr/local/lib/python3.8/dist-packages/airflow/example_dags/example_trigger_target_dag.py
[2020-06-01 14:55:35,623] {scheduler_job.py:1574} INFO - DAG(s) dict_keys(['example_trigger_target_dag']) retrieved from /usr/local/lib/python3.8/dist-packages/airflow/example_dags/example_trigger_target_dag.py
[2020-06-01 14:55:35,823] {scheduler_job.py:161} INFO - Processing /usr/local/lib/python3.8/dist-packages/airflow/example_dags/example_trigger_target_dag.py took 0.223 seconds
[2020-06-01 14:56:23,590] {scheduler_job.py:153} INFO - Started process (PID=679) to work on /usr/local/lib/python3.8/dist-packages/airflow/example_dags/example_trigger_target_dag.py
[2020-06-01 14:56:23,596] {scheduler_job.py:1562} INFO - Processing file /usr/local/lib/python3.8/dist-packages/airflow/example_dags/example_trigger_target_dag.py for tasks to queue
[2020-06-01 14:56:23,596] {logging_mixin.py:112} INFO - [2020-06-01 14:56:23,596] {dagbag.py:396} INFO - Filling up the DagBag from /usr/local/lib/python3.8/dist-packages/airflow/example_dags/example_trigger_target_dag.py
[2020-06-01 14:56:23,607] {scheduler_job.py:1574} INFO - DAG(s) dict_keys(['example_trigger_target_dag']) retrieved from /usr/local/lib/python3.8/dist-packages/airflow/example_dags/example_trigger_target_dag.py
[2020-06-01 14:56:23,729] {scheduler_job.py:166} ERROR - Got an exception! Propagating...
Traceback (most recent call last):
  File "/usr/local/lib/python3.8/dist-packages/sqlalchemy/engine/base.py", line 774, in _commit_impl
    self.engine.dialect.do_commit(self.connection)
  File "/usr/local/lib/python3.8/dist-packages/sqlalchemy/engine/default.py", line 543, in do_commit
    dbapi_connection.commit()
sqlite3.OperationalError: disk I/O error

The above exception was the direct cause of the following exception:

Traceback (most recent call last):
  File "/usr/local/lib/python3.8/dist-packages/airflow/jobs/scheduler_job.py", line 156, in _run_file_processor
    result = scheduler_job.process_file(file_path,
  File "/usr/local/lib/python3.8/dist-packages/airflow/utils/db.py", line 74, in wrapper
    return func(*args, **kwargs)
  File "/usr/local/lib/python3.8/dist-packages/airflow/jobs/scheduler_job.py", line 1582, in process_file
    dag.sync_to_db()
  File "/usr/local/lib/python3.8/dist-packages/airflow/utils/db.py", line 74, in wrapper
    return func(*args, **kwargs)
  File "/usr/local/lib/python3.8/dist-packages/airflow/models/dag.py", line 1516, in sync_to_db
    orm_dag.tags = self.get_dagtags(session=session)
  File "/usr/local/lib/python3.8/dist-packages/airflow/utils/db.py", line 70, in wrapper
    return func(*args, **kwargs)
  File "/usr/local/lib/python3.8/dist-packages/airflow/models/dag.py", line 1555, in get_dagtags
    session.commit()
  File "/usr/local/lib/python3.8/dist-packages/sqlalchemy/orm/session.py", line 1042, in commit
    self.transaction.commit()
  File "/usr/local/lib/python3.8/dist-packages/sqlalchemy/orm/session.py", line 508, in commit
    t[1].commit()
  File "/usr/local/lib/python3.8/dist-packages/sqlalchemy/engine/base.py", line 1771, in commit
    self._do_commit()
  File "/usr/local/lib/python3.8/dist-packages/sqlalchemy/engine/base.py", line 1802, in _do_commit
    self.connection._commit_impl()
  File "/usr/local/lib/python3.8/dist-packages/sqlalchemy/engine/base.py", line 776, in _commit_impl
    self._handle_dbapi_exception(e, None, None, None, None)
  File "/usr/local/lib/python3.8/dist-packages/sqlalchemy/engine/base.py", line 1517, in _handle_dbapi_exception
    util.raise_(
  File "/usr/local/lib/python3.8/dist-packages/sqlalchemy/util/compat.py", line 178, in raise_
    raise exception
  File "/usr/local/lib/python3.8/dist-packages/sqlalchemy/engine/base.py", line 774, in _commit_impl
    self.engine.dialect.do_commit(self.connection)
  File "/usr/local/lib/python3.8/dist-packages/sqlalchemy/engine/default.py", line 543, in do_commit
    dbapi_connection.commit()
sqlalchemy.exc.OperationalError: (sqlite3.OperationalError) disk I/O error
(Background on this error at: http://sqlalche.me/e/e3q8)
[2020-06-01 14:57:02,201] {scheduler_job.py:153} INFO - Started process (PID=723) to work on /usr/local/lib/python3.8/dist-packages/airflow/example_dags/example_trigger_target_dag.py
[2020-06-01 14:57:02,207] {scheduler_job.py:1562} INFO - Processing file /usr/local/lib/python3.8/dist-packages/airflow/example_dags/example_trigger_target_dag.py for tasks to queue
[2020-06-01 14:57:02,208] {logging_mixin.py:112} INFO - [2020-06-01 14:57:02,208] {dagbag.py:396} INFO - Filling up the DagBag from /usr/local/lib/python3.8/dist-packages/airflow/example_dags/example_trigger_target_dag.py
[2020-06-01 14:57:02,223] {scheduler_job.py:1574} INFO - DAG(s) dict_keys(['example_trigger_target_dag']) retrieved from /usr/local/lib/python3.8/dist-packages/airflow/example_dags/example_trigger_target_dag.py
[2020-06-01 14:57:02,404] {scheduler_job.py:161} INFO - Processing /usr/local/lib/python3.8/dist-packages/airflow/example_dags/example_trigger_target_dag.py took 0.203 seconds
[2020-06-01 14:57:50,237] {scheduler_job.py:153} INFO - Started process (PID=751) to work on /usr/local/lib/python3.8/dist-packages/airflow/example_dags/example_trigger_target_dag.py
[2020-06-01 14:57:50,242] {scheduler_job.py:1562} INFO - Processing file /usr/local/lib/python3.8/dist-packages/airflow/example_dags/example_trigger_target_dag.py for tasks to queue
[2020-06-01 14:57:50,243] {logging_mixin.py:112} INFO - [2020-06-01 14:57:50,242] {dagbag.py:396} INFO - Filling up the DagBag from /usr/local/lib/python3.8/dist-packages/airflow/example_dags/example_trigger_target_dag.py
[2020-06-01 14:57:50,253] {scheduler_job.py:1574} INFO - DAG(s) dict_keys(['example_trigger_target_dag']) retrieved from /usr/local/lib/python3.8/dist-packages/airflow/example_dags/example_trigger_target_dag.py
[2020-06-01 14:57:50,409] {scheduler_job.py:166} ERROR - Got an exception! Propagating...
Traceback (most recent call last):
  File "/usr/local/lib/python3.8/dist-packages/sqlalchemy/engine/base.py", line 774, in _commit_impl
    self.engine.dialect.do_commit(self.connection)
  File "/usr/local/lib/python3.8/dist-packages/sqlalchemy/engine/default.py", line 543, in do_commit
    dbapi_connection.commit()
sqlite3.OperationalError: disk I/O error

The above exception was the direct cause of the following exception:

Traceback (most recent call last):
  File "/usr/local/lib/python3.8/dist-packages/airflow/jobs/scheduler_job.py", line 156, in _run_file_processor
    result = scheduler_job.process_file(file_path,
  File "/usr/local/lib/python3.8/dist-packages/airflow/utils/db.py", line 74, in wrapper
    return func(*args, **kwargs)
  File "/usr/local/lib/python3.8/dist-packages/airflow/jobs/scheduler_job.py", line 1582, in process_file
    dag.sync_to_db()
  File "/usr/local/lib/python3.8/dist-packages/airflow/utils/db.py", line 74, in wrapper
    return func(*args, **kwargs)
  File "/usr/local/lib/python3.8/dist-packages/airflow/models/dag.py", line 1516, in sync_to_db
    orm_dag.tags = self.get_dagtags(session=session)
  File "/usr/local/lib/python3.8/dist-packages/airflow/utils/db.py", line 70, in wrapper
    return func(*args, **kwargs)
  File "/usr/local/lib/python3.8/dist-packages/airflow/models/dag.py", line 1555, in get_dagtags
    session.commit()
  File "/usr/local/lib/python3.8/dist-packages/sqlalchemy/orm/session.py", line 1042, in commit
    self.transaction.commit()
  File "/usr/local/lib/python3.8/dist-packages/sqlalchemy/orm/session.py", line 508, in commit
    t[1].commit()
  File "/usr/local/lib/python3.8/dist-packages/sqlalchemy/engine/base.py", line 1771, in commit
    self._do_commit()
  File "/usr/local/lib/python3.8/dist-packages/sqlalchemy/engine/base.py", line 1802, in _do_commit
    self.connection._commit_impl()
  File "/usr/local/lib/python3.8/dist-packages/sqlalchemy/engine/base.py", line 776, in _commit_impl
    self._handle_dbapi_exception(e, None, None, None, None)
  File "/usr/local/lib/python3.8/dist-packages/sqlalchemy/engine/base.py", line 1517, in _handle_dbapi_exception
    util.raise_(
  File "/usr/local/lib/python3.8/dist-packages/sqlalchemy/util/compat.py", line 178, in raise_
    raise exception
  File "/usr/local/lib/python3.8/dist-packages/sqlalchemy/engine/base.py", line 774, in _commit_impl
    self.engine.dialect.do_commit(self.connection)
  File "/usr/local/lib/python3.8/dist-packages/sqlalchemy/engine/default.py", line 543, in do_commit
    dbapi_connection.commit()
sqlalchemy.exc.OperationalError: (sqlite3.OperationalError) disk I/O error
(Background on this error at: http://sqlalche.me/e/e3q8)
[2020-06-01 14:58:39,076] {scheduler_job.py:153} INFO - Started process (PID=779) to work on /usr/local/lib/python3.8/dist-packages/airflow/example_dags/example_trigger_target_dag.py
[2020-06-01 14:58:39,081] {scheduler_job.py:1562} INFO - Processing file /usr/local/lib/python3.8/dist-packages/airflow/example_dags/example_trigger_target_dag.py for tasks to queue
[2020-06-01 14:58:39,082] {logging_mixin.py:112} INFO - [2020-06-01 14:58:39,081] {dagbag.py:396} INFO - Filling up the DagBag from /usr/local/lib/python3.8/dist-packages/airflow/example_dags/example_trigger_target_dag.py
[2020-06-01 14:58:39,092] {scheduler_job.py:1574} INFO - DAG(s) dict_keys(['example_trigger_target_dag']) retrieved from /usr/local/lib/python3.8/dist-packages/airflow/example_dags/example_trigger_target_dag.py
[2020-06-01 14:58:39,271] {scheduler_job.py:166} ERROR - Got an exception! Propagating...
Traceback (most recent call last):
  File "/usr/local/lib/python3.8/dist-packages/sqlalchemy/engine/base.py", line 774, in _commit_impl
    self.engine.dialect.do_commit(self.connection)
  File "/usr/local/lib/python3.8/dist-packages/sqlalchemy/engine/default.py", line 543, in do_commit
    dbapi_connection.commit()
sqlite3.OperationalError: disk I/O error

The above exception was the direct cause of the following exception:

Traceback (most recent call last):
  File "/usr/local/lib/python3.8/dist-packages/airflow/jobs/scheduler_job.py", line 156, in _run_file_processor
    result = scheduler_job.process_file(file_path,
  File "/usr/local/lib/python3.8/dist-packages/airflow/utils/db.py", line 74, in wrapper
    return func(*args, **kwargs)
  File "/usr/local/lib/python3.8/dist-packages/airflow/jobs/scheduler_job.py", line 1582, in process_file
    dag.sync_to_db()
  File "/usr/local/lib/python3.8/dist-packages/airflow/utils/db.py", line 74, in wrapper
    return func(*args, **kwargs)
  File "/usr/local/lib/python3.8/dist-packages/airflow/models/dag.py", line 1516, in sync_to_db
    orm_dag.tags = self.get_dagtags(session=session)
  File "/usr/local/lib/python3.8/dist-packages/airflow/utils/db.py", line 70, in wrapper
    return func(*args, **kwargs)
  File "/usr/local/lib/python3.8/dist-packages/airflow/models/dag.py", line 1555, in get_dagtags
    session.commit()
  File "/usr/local/lib/python3.8/dist-packages/sqlalchemy/orm/session.py", line 1042, in commit
    self.transaction.commit()
  File "/usr/local/lib/python3.8/dist-packages/sqlalchemy/orm/session.py", line 508, in commit
    t[1].commit()
  File "/usr/local/lib/python3.8/dist-packages/sqlalchemy/engine/base.py", line 1771, in commit
    self._do_commit()
  File "/usr/local/lib/python3.8/dist-packages/sqlalchemy/engine/base.py", line 1802, in _do_commit
    self.connection._commit_impl()
  File "/usr/local/lib/python3.8/dist-packages/sqlalchemy/engine/base.py", line 776, in _commit_impl
    self._handle_dbapi_exception(e, None, None, None, None)
  File "/usr/local/lib/python3.8/dist-packages/sqlalchemy/engine/base.py", line 1517, in _handle_dbapi_exception
    util.raise_(
  File "/usr/local/lib/python3.8/dist-packages/sqlalchemy/util/compat.py", line 178, in raise_
    raise exception
  File "/usr/local/lib/python3.8/dist-packages/sqlalchemy/engine/base.py", line 774, in _commit_impl
    self.engine.dialect.do_commit(self.connection)
  File "/usr/local/lib/python3.8/dist-packages/sqlalchemy/engine/default.py", line 543, in do_commit
    dbapi_connection.commit()
sqlalchemy.exc.OperationalError: (sqlite3.OperationalError) disk I/O error
(Background on this error at: http://sqlalche.me/e/e3q8)
[2020-06-01 14:59:27,146] {scheduler_job.py:153} INFO - Started process (PID=811) to work on /usr/local/lib/python3.8/dist-packages/airflow/example_dags/example_trigger_target_dag.py
[2020-06-01 14:59:27,155] {scheduler_job.py:1562} INFO - Processing file /usr/local/lib/python3.8/dist-packages/airflow/example_dags/example_trigger_target_dag.py for tasks to queue
[2020-06-01 14:59:27,156] {logging_mixin.py:112} INFO - [2020-06-01 14:59:27,156] {dagbag.py:396} INFO - Filling up the DagBag from /usr/local/lib/python3.8/dist-packages/airflow/example_dags/example_trigger_target_dag.py
[2020-06-01 14:59:27,171] {scheduler_job.py:1574} INFO - DAG(s) dict_keys(['example_trigger_target_dag']) retrieved from /usr/local/lib/python3.8/dist-packages/airflow/example_dags/example_trigger_target_dag.py
[2020-06-01 14:59:27,351] {scheduler_job.py:166} ERROR - Got an exception! Propagating...
Traceback (most recent call last):
  File "/usr/local/lib/python3.8/dist-packages/sqlalchemy/engine/base.py", line 774, in _commit_impl
    self.engine.dialect.do_commit(self.connection)
  File "/usr/local/lib/python3.8/dist-packages/sqlalchemy/engine/default.py", line 543, in do_commit
    dbapi_connection.commit()
sqlite3.OperationalError: disk I/O error

The above exception was the direct cause of the following exception:

Traceback (most recent call last):
  File "/usr/local/lib/python3.8/dist-packages/airflow/jobs/scheduler_job.py", line 156, in _run_file_processor
    result = scheduler_job.process_file(file_path,
  File "/usr/local/lib/python3.8/dist-packages/airflow/utils/db.py", line 74, in wrapper
    return func(*args, **kwargs)
  File "/usr/local/lib/python3.8/dist-packages/airflow/jobs/scheduler_job.py", line 1582, in process_file
    dag.sync_to_db()
  File "/usr/local/lib/python3.8/dist-packages/airflow/utils/db.py", line 74, in wrapper
    return func(*args, **kwargs)
  File "/usr/local/lib/python3.8/dist-packages/airflow/models/dag.py", line 1516, in sync_to_db
    orm_dag.tags = self.get_dagtags(session=session)
  File "/usr/local/lib/python3.8/dist-packages/airflow/utils/db.py", line 70, in wrapper
    return func(*args, **kwargs)
  File "/usr/local/lib/python3.8/dist-packages/airflow/models/dag.py", line 1555, in get_dagtags
    session.commit()
  File "/usr/local/lib/python3.8/dist-packages/sqlalchemy/orm/session.py", line 1042, in commit
    self.transaction.commit()
  File "/usr/local/lib/python3.8/dist-packages/sqlalchemy/orm/session.py", line 508, in commit
    t[1].commit()
  File "/usr/local/lib/python3.8/dist-packages/sqlalchemy/engine/base.py", line 1771, in commit
    self._do_commit()
  File "/usr/local/lib/python3.8/dist-packages/sqlalchemy/engine/base.py", line 1802, in _do_commit
    self.connection._commit_impl()
  File "/usr/local/lib/python3.8/dist-packages/sqlalchemy/engine/base.py", line 776, in _commit_impl
    self._handle_dbapi_exception(e, None, None, None, None)
  File "/usr/local/lib/python3.8/dist-packages/sqlalchemy/engine/base.py", line 1517, in _handle_dbapi_exception
    util.raise_(
  File "/usr/local/lib/python3.8/dist-packages/sqlalchemy/util/compat.py", line 178, in raise_
    raise exception
  File "/usr/local/lib/python3.8/dist-packages/sqlalchemy/engine/base.py", line 774, in _commit_impl
    self.engine.dialect.do_commit(self.connection)
  File "/usr/local/lib/python3.8/dist-packages/sqlalchemy/engine/default.py", line 543, in do_commit
    dbapi_connection.commit()
sqlalchemy.exc.OperationalError: (sqlite3.OperationalError) disk I/O error
(Background on this error at: http://sqlalche.me/e/e3q8)
[2020-06-01 15:00:15,210] {scheduler_job.py:153} INFO - Started process (PID=839) to work on /usr/local/lib/python3.8/dist-packages/airflow/example_dags/example_trigger_target_dag.py
[2020-06-01 15:00:15,216] {scheduler_job.py:1562} INFO - Processing file /usr/local/lib/python3.8/dist-packages/airflow/example_dags/example_trigger_target_dag.py for tasks to queue
[2020-06-01 15:00:15,217] {logging_mixin.py:112} INFO - [2020-06-01 15:00:15,217] {dagbag.py:396} INFO - Filling up the DagBag from /usr/local/lib/python3.8/dist-packages/airflow/example_dags/example_trigger_target_dag.py
[2020-06-01 15:00:15,229] {scheduler_job.py:1574} INFO - DAG(s) dict_keys(['example_trigger_target_dag']) retrieved from /usr/local/lib/python3.8/dist-packages/airflow/example_dags/example_trigger_target_dag.py
[2020-06-01 15:00:15,461] {scheduler_job.py:166} ERROR - Got an exception! Propagating...
Traceback (most recent call last):
  File "/usr/local/lib/python3.8/dist-packages/sqlalchemy/engine/base.py", line 774, in _commit_impl
    self.engine.dialect.do_commit(self.connection)
  File "/usr/local/lib/python3.8/dist-packages/sqlalchemy/engine/default.py", line 543, in do_commit
    dbapi_connection.commit()
sqlite3.OperationalError: disk I/O error

The above exception was the direct cause of the following exception:

Traceback (most recent call last):
  File "/usr/local/lib/python3.8/dist-packages/airflow/jobs/scheduler_job.py", line 156, in _run_file_processor
    result = scheduler_job.process_file(file_path,
  File "/usr/local/lib/python3.8/dist-packages/airflow/utils/db.py", line 74, in wrapper
    return func(*args, **kwargs)
  File "/usr/local/lib/python3.8/dist-packages/airflow/jobs/scheduler_job.py", line 1582, in process_file
    dag.sync_to_db()
  File "/usr/local/lib/python3.8/dist-packages/airflow/utils/db.py", line 74, in wrapper
    return func(*args, **kwargs)
  File "/usr/local/lib/python3.8/dist-packages/airflow/models/dag.py", line 1516, in sync_to_db
    orm_dag.tags = self.get_dagtags(session=session)
  File "/usr/local/lib/python3.8/dist-packages/airflow/utils/db.py", line 70, in wrapper
    return func(*args, **kwargs)
  File "/usr/local/lib/python3.8/dist-packages/airflow/models/dag.py", line 1555, in get_dagtags
    session.commit()
  File "/usr/local/lib/python3.8/dist-packages/sqlalchemy/orm/session.py", line 1042, in commit
    self.transaction.commit()
  File "/usr/local/lib/python3.8/dist-packages/sqlalchemy/orm/session.py", line 508, in commit
    t[1].commit()
  File "/usr/local/lib/python3.8/dist-packages/sqlalchemy/engine/base.py", line 1771, in commit
    self._do_commit()
  File "/usr/local/lib/python3.8/dist-packages/sqlalchemy/engine/base.py", line 1802, in _do_commit
    self.connection._commit_impl()
  File "/usr/local/lib/python3.8/dist-packages/sqlalchemy/engine/base.py", line 776, in _commit_impl
    self._handle_dbapi_exception(e, None, None, None, None)
  File "/usr/local/lib/python3.8/dist-packages/sqlalchemy/engine/base.py", line 1517, in _handle_dbapi_exception
    util.raise_(
  File "/usr/local/lib/python3.8/dist-packages/sqlalchemy/util/compat.py", line 178, in raise_
    raise exception
  File "/usr/local/lib/python3.8/dist-packages/sqlalchemy/engine/base.py", line 774, in _commit_impl
    self.engine.dialect.do_commit(self.connection)
  File "/usr/local/lib/python3.8/dist-packages/sqlalchemy/engine/default.py", line 543, in do_commit
    dbapi_connection.commit()
sqlalchemy.exc.OperationalError: (sqlite3.OperationalError) disk I/O error
(Background on this error at: http://sqlalche.me/e/e3q8)
[2020-06-01 15:01:03,275] {scheduler_job.py:153} INFO - Started process (PID=871) to work on /usr/local/lib/python3.8/dist-packages/airflow/example_dags/example_trigger_target_dag.py
[2020-06-01 15:01:03,282] {scheduler_job.py:1562} INFO - Processing file /usr/local/lib/python3.8/dist-packages/airflow/example_dags/example_trigger_target_dag.py for tasks to queue
[2020-06-01 15:01:03,283] {logging_mixin.py:112} INFO - [2020-06-01 15:01:03,283] {dagbag.py:396} INFO - Filling up the DagBag from /usr/local/lib/python3.8/dist-packages/airflow/example_dags/example_trigger_target_dag.py
[2020-06-01 15:01:03,296] {scheduler_job.py:1574} INFO - DAG(s) dict_keys(['example_trigger_target_dag']) retrieved from /usr/local/lib/python3.8/dist-packages/airflow/example_dags/example_trigger_target_dag.py
[2020-06-01 15:01:03,516] {scheduler_job.py:166} ERROR - Got an exception! Propagating...
Traceback (most recent call last):
  File "/usr/local/lib/python3.8/dist-packages/sqlalchemy/engine/base.py", line 774, in _commit_impl
    self.engine.dialect.do_commit(self.connection)
  File "/usr/local/lib/python3.8/dist-packages/sqlalchemy/engine/default.py", line 543, in do_commit
    dbapi_connection.commit()
sqlite3.OperationalError: disk I/O error

The above exception was the direct cause of the following exception:

Traceback (most recent call last):
  File "/usr/local/lib/python3.8/dist-packages/airflow/jobs/scheduler_job.py", line 156, in _run_file_processor
    result = scheduler_job.process_file(file_path,
  File "/usr/local/lib/python3.8/dist-packages/airflow/utils/db.py", line 74, in wrapper
    return func(*args, **kwargs)
  File "/usr/local/lib/python3.8/dist-packages/airflow/jobs/scheduler_job.py", line 1582, in process_file
    dag.sync_to_db()
  File "/usr/local/lib/python3.8/dist-packages/airflow/utils/db.py", line 74, in wrapper
    return func(*args, **kwargs)
  File "/usr/local/lib/python3.8/dist-packages/airflow/models/dag.py", line 1516, in sync_to_db
    orm_dag.tags = self.get_dagtags(session=session)
  File "/usr/local/lib/python3.8/dist-packages/airflow/utils/db.py", line 70, in wrapper
    return func(*args, **kwargs)
  File "/usr/local/lib/python3.8/dist-packages/airflow/models/dag.py", line 1555, in get_dagtags
    session.commit()
  File "/usr/local/lib/python3.8/dist-packages/sqlalchemy/orm/session.py", line 1042, in commit
    self.transaction.commit()
  File "/usr/local/lib/python3.8/dist-packages/sqlalchemy/orm/session.py", line 508, in commit
    t[1].commit()
  File "/usr/local/lib/python3.8/dist-packages/sqlalchemy/engine/base.py", line 1771, in commit
    self._do_commit()
  File "/usr/local/lib/python3.8/dist-packages/sqlalchemy/engine/base.py", line 1802, in _do_commit
    self.connection._commit_impl()
  File "/usr/local/lib/python3.8/dist-packages/sqlalchemy/engine/base.py", line 776, in _commit_impl
    self._handle_dbapi_exception(e, None, None, None, None)
  File "/usr/local/lib/python3.8/dist-packages/sqlalchemy/engine/base.py", line 1517, in _handle_dbapi_exception
    util.raise_(
  File "/usr/local/lib/python3.8/dist-packages/sqlalchemy/util/compat.py", line 178, in raise_
    raise exception
  File "/usr/local/lib/python3.8/dist-packages/sqlalchemy/engine/base.py", line 774, in _commit_impl
    self.engine.dialect.do_commit(self.connection)
  File "/usr/local/lib/python3.8/dist-packages/sqlalchemy/engine/default.py", line 543, in do_commit
    dbapi_connection.commit()
sqlalchemy.exc.OperationalError: (sqlite3.OperationalError) disk I/O error
(Background on this error at: http://sqlalche.me/e/e3q8)
[2020-06-01 15:01:51,347] {scheduler_job.py:153} INFO - Started process (PID=903) to work on /usr/local/lib/python3.8/dist-packages/airflow/example_dags/example_trigger_target_dag.py
[2020-06-01 15:01:51,354] {scheduler_job.py:1562} INFO - Processing file /usr/local/lib/python3.8/dist-packages/airflow/example_dags/example_trigger_target_dag.py for tasks to queue
[2020-06-01 15:01:51,354] {logging_mixin.py:112} INFO - [2020-06-01 15:01:51,354] {dagbag.py:396} INFO - Filling up the DagBag from /usr/local/lib/python3.8/dist-packages/airflow/example_dags/example_trigger_target_dag.py
[2020-06-01 15:01:51,365] {scheduler_job.py:1574} INFO - DAG(s) dict_keys(['example_trigger_target_dag']) retrieved from /usr/local/lib/python3.8/dist-packages/airflow/example_dags/example_trigger_target_dag.py
[2020-06-01 15:01:51,592] {scheduler_job.py:161} INFO - Processing /usr/local/lib/python3.8/dist-packages/airflow/example_dags/example_trigger_target_dag.py took 0.246 seconds
[2020-06-01 15:02:39,373] {scheduler_job.py:153} INFO - Started process (PID=931) to work on /usr/local/lib/python3.8/dist-packages/airflow/example_dags/example_trigger_target_dag.py
[2020-06-01 15:02:39,380] {scheduler_job.py:1562} INFO - Processing file /usr/local/lib/python3.8/dist-packages/airflow/example_dags/example_trigger_target_dag.py for tasks to queue
[2020-06-01 15:02:39,380] {logging_mixin.py:112} INFO - [2020-06-01 15:02:39,380] {dagbag.py:396} INFO - Filling up the DagBag from /usr/local/lib/python3.8/dist-packages/airflow/example_dags/example_trigger_target_dag.py
[2020-06-01 15:02:39,391] {scheduler_job.py:1574} INFO - DAG(s) dict_keys(['example_trigger_target_dag']) retrieved from /usr/local/lib/python3.8/dist-packages/airflow/example_dags/example_trigger_target_dag.py
[2020-06-01 15:02:39,559] {scheduler_job.py:166} ERROR - Got an exception! Propagating...
Traceback (most recent call last):
  File "/usr/local/lib/python3.8/dist-packages/sqlalchemy/engine/base.py", line 774, in _commit_impl
    self.engine.dialect.do_commit(self.connection)
  File "/usr/local/lib/python3.8/dist-packages/sqlalchemy/engine/default.py", line 543, in do_commit
    dbapi_connection.commit()
sqlite3.OperationalError: disk I/O error

The above exception was the direct cause of the following exception:

Traceback (most recent call last):
  File "/usr/local/lib/python3.8/dist-packages/airflow/jobs/scheduler_job.py", line 156, in _run_file_processor
    result = scheduler_job.process_file(file_path,
  File "/usr/local/lib/python3.8/dist-packages/airflow/utils/db.py", line 74, in wrapper
    return func(*args, **kwargs)
  File "/usr/local/lib/python3.8/dist-packages/airflow/jobs/scheduler_job.py", line 1582, in process_file
    dag.sync_to_db()
  File "/usr/local/lib/python3.8/dist-packages/airflow/utils/db.py", line 74, in wrapper
    return func(*args, **kwargs)
  File "/usr/local/lib/python3.8/dist-packages/airflow/models/dag.py", line 1516, in sync_to_db
    orm_dag.tags = self.get_dagtags(session=session)
  File "/usr/local/lib/python3.8/dist-packages/airflow/utils/db.py", line 70, in wrapper
    return func(*args, **kwargs)
  File "/usr/local/lib/python3.8/dist-packages/airflow/models/dag.py", line 1555, in get_dagtags
    session.commit()
  File "/usr/local/lib/python3.8/dist-packages/sqlalchemy/orm/session.py", line 1042, in commit
    self.transaction.commit()
  File "/usr/local/lib/python3.8/dist-packages/sqlalchemy/orm/session.py", line 508, in commit
    t[1].commit()
  File "/usr/local/lib/python3.8/dist-packages/sqlalchemy/engine/base.py", line 1771, in commit
    self._do_commit()
  File "/usr/local/lib/python3.8/dist-packages/sqlalchemy/engine/base.py", line 1802, in _do_commit
    self.connection._commit_impl()
  File "/usr/local/lib/python3.8/dist-packages/sqlalchemy/engine/base.py", line 776, in _commit_impl
    self._handle_dbapi_exception(e, None, None, None, None)
  File "/usr/local/lib/python3.8/dist-packages/sqlalchemy/engine/base.py", line 1517, in _handle_dbapi_exception
    util.raise_(
  File "/usr/local/lib/python3.8/dist-packages/sqlalchemy/util/compat.py", line 178, in raise_
    raise exception
  File "/usr/local/lib/python3.8/dist-packages/sqlalchemy/engine/base.py", line 774, in _commit_impl
    self.engine.dialect.do_commit(self.connection)
  File "/usr/local/lib/python3.8/dist-packages/sqlalchemy/engine/default.py", line 543, in do_commit
    dbapi_connection.commit()
sqlalchemy.exc.OperationalError: (sqlite3.OperationalError) disk I/O error
(Background on this error at: http://sqlalche.me/e/e3q8)
[2020-06-01 15:03:27,442] {scheduler_job.py:153} INFO - Started process (PID=963) to work on /usr/local/lib/python3.8/dist-packages/airflow/example_dags/example_trigger_target_dag.py
[2020-06-01 15:03:27,450] {scheduler_job.py:1562} INFO - Processing file /usr/local/lib/python3.8/dist-packages/airflow/example_dags/example_trigger_target_dag.py for tasks to queue
[2020-06-01 15:03:27,450] {logging_mixin.py:112} INFO - [2020-06-01 15:03:27,450] {dagbag.py:396} INFO - Filling up the DagBag from /usr/local/lib/python3.8/dist-packages/airflow/example_dags/example_trigger_target_dag.py
[2020-06-01 15:03:27,471] {scheduler_job.py:1574} INFO - DAG(s) dict_keys(['example_trigger_target_dag']) retrieved from /usr/local/lib/python3.8/dist-packages/airflow/example_dags/example_trigger_target_dag.py
[2020-06-01 15:03:27,662] {scheduler_job.py:161} INFO - Processing /usr/local/lib/python3.8/dist-packages/airflow/example_dags/example_trigger_target_dag.py took 0.221 seconds
