[2020-06-01 14:51:09,564] {scheduler_job.py:153} INFO - Started process (PID=455) to work on /usr/local/lib/python3.8/dist-packages/airflow/example_dags/example_subdag_operator.py
[2020-06-01 14:51:09,569] {scheduler_job.py:1562} INFO - Processing file /usr/local/lib/python3.8/dist-packages/airflow/example_dags/example_subdag_operator.py for tasks to queue
[2020-06-01 14:51:09,570] {logging_mixin.py:112} INFO - [2020-06-01 14:51:09,570] {dagbag.py:396} INFO - Filling up the DagBag from /usr/local/lib/python3.8/dist-packages/airflow/example_dags/example_subdag_operator.py
[2020-06-01 14:51:09,593] {scheduler_job.py:1574} INFO - DAG(s) dict_keys(['example_subdag_operator.section-1', 'example_subdag_operator.section-2', 'example_subdag_operator']) retrieved from /usr/local/lib/python3.8/dist-packages/airflow/example_dags/example_subdag_operator.py
[2020-06-01 14:51:10,280] {scheduler_job.py:161} INFO - Processing /usr/local/lib/python3.8/dist-packages/airflow/example_dags/example_subdag_operator.py took 0.717 seconds
[2020-06-01 14:52:59,349] {scheduler_job.py:153} INFO - Started process (PID=518) to work on /usr/local/lib/python3.8/dist-packages/airflow/example_dags/example_subdag_operator.py
[2020-06-01 14:52:59,354] {scheduler_job.py:1562} INFO - Processing file /usr/local/lib/python3.8/dist-packages/airflow/example_dags/example_subdag_operator.py for tasks to queue
[2020-06-01 14:52:59,355] {logging_mixin.py:112} INFO - [2020-06-01 14:52:59,355] {dagbag.py:396} INFO - Filling up the DagBag from /usr/local/lib/python3.8/dist-packages/airflow/example_dags/example_subdag_operator.py
[2020-06-01 14:52:59,394] {scheduler_job.py:1574} INFO - DAG(s) dict_keys(['example_subdag_operator.section-1', 'example_subdag_operator.section-2', 'example_subdag_operator']) retrieved from /usr/local/lib/python3.8/dist-packages/airflow/example_dags/example_subdag_operator.py
[2020-06-01 14:52:59,954] {scheduler_job.py:161} INFO - Processing /usr/local/lib/python3.8/dist-packages/airflow/example_dags/example_subdag_operator.py took 0.605 seconds
[2020-06-01 14:53:47,437] {scheduler_job.py:153} INFO - Started process (PID=581) to work on /usr/local/lib/python3.8/dist-packages/airflow/example_dags/example_subdag_operator.py
[2020-06-01 14:53:47,442] {scheduler_job.py:1562} INFO - Processing file /usr/local/lib/python3.8/dist-packages/airflow/example_dags/example_subdag_operator.py for tasks to queue
[2020-06-01 14:53:47,442] {logging_mixin.py:112} INFO - [2020-06-01 14:53:47,442] {dagbag.py:396} INFO - Filling up the DagBag from /usr/local/lib/python3.8/dist-packages/airflow/example_dags/example_subdag_operator.py
[2020-06-01 14:53:47,479] {scheduler_job.py:1574} INFO - DAG(s) dict_keys(['example_subdag_operator.section-1', 'example_subdag_operator.section-2', 'example_subdag_operator']) retrieved from /usr/local/lib/python3.8/dist-packages/airflow/example_dags/example_subdag_operator.py
[2020-06-01 14:53:47,641] {scheduler_job.py:166} ERROR - Got an exception! Propagating...
Traceback (most recent call last):
  File "/usr/local/lib/python3.8/dist-packages/sqlalchemy/engine/base.py", line 774, in _commit_impl
    self.engine.dialect.do_commit(self.connection)
  File "/usr/local/lib/python3.8/dist-packages/sqlalchemy/engine/default.py", line 543, in do_commit
    dbapi_connection.commit()
sqlite3.OperationalError: disk I/O error

The above exception was the direct cause of the following exception:

Traceback (most recent call last):
  File "/usr/local/lib/python3.8/dist-packages/airflow/jobs/scheduler_job.py", line 156, in _run_file_processor
    result = scheduler_job.process_file(file_path,
  File "/usr/local/lib/python3.8/dist-packages/airflow/utils/db.py", line 74, in wrapper
    return func(*args, **kwargs)
  File "/usr/local/lib/python3.8/dist-packages/airflow/jobs/scheduler_job.py", line 1582, in process_file
    dag.sync_to_db()
  File "/usr/local/lib/python3.8/dist-packages/airflow/utils/db.py", line 74, in wrapper
    return func(*args, **kwargs)
  File "/usr/local/lib/python3.8/dist-packages/airflow/models/dag.py", line 1521, in sync_to_db
    session.commit()
  File "/usr/local/lib/python3.8/dist-packages/sqlalchemy/orm/session.py", line 1042, in commit
    self.transaction.commit()
  File "/usr/local/lib/python3.8/dist-packages/sqlalchemy/orm/session.py", line 508, in commit
    t[1].commit()
  File "/usr/local/lib/python3.8/dist-packages/sqlalchemy/engine/base.py", line 1771, in commit
    self._do_commit()
  File "/usr/local/lib/python3.8/dist-packages/sqlalchemy/engine/base.py", line 1802, in _do_commit
    self.connection._commit_impl()
  File "/usr/local/lib/python3.8/dist-packages/sqlalchemy/engine/base.py", line 776, in _commit_impl
    self._handle_dbapi_exception(e, None, None, None, None)
  File "/usr/local/lib/python3.8/dist-packages/sqlalchemy/engine/base.py", line 1517, in _handle_dbapi_exception
    util.raise_(
  File "/usr/local/lib/python3.8/dist-packages/sqlalchemy/util/compat.py", line 178, in raise_
    raise exception
  File "/usr/local/lib/python3.8/dist-packages/sqlalchemy/engine/base.py", line 774, in _commit_impl
    self.engine.dialect.do_commit(self.connection)
  File "/usr/local/lib/python3.8/dist-packages/sqlalchemy/engine/default.py", line 543, in do_commit
    dbapi_connection.commit()
sqlalchemy.exc.OperationalError: (sqlite3.OperationalError) disk I/O error
(Background on this error at: http://sqlalche.me/e/e3q8)
[2020-06-01 14:54:35,497] {scheduler_job.py:153} INFO - Started process (PID=613) to work on /usr/local/lib/python3.8/dist-packages/airflow/example_dags/example_subdag_operator.py
[2020-06-01 14:54:35,502] {scheduler_job.py:1562} INFO - Processing file /usr/local/lib/python3.8/dist-packages/airflow/example_dags/example_subdag_operator.py for tasks to queue
[2020-06-01 14:54:35,503] {logging_mixin.py:112} INFO - [2020-06-01 14:54:35,503] {dagbag.py:396} INFO - Filling up the DagBag from /usr/local/lib/python3.8/dist-packages/airflow/example_dags/example_subdag_operator.py
[2020-06-01 14:54:35,524] {scheduler_job.py:1574} INFO - DAG(s) dict_keys(['example_subdag_operator.section-1', 'example_subdag_operator.section-2', 'example_subdag_operator']) retrieved from /usr/local/lib/python3.8/dist-packages/airflow/example_dags/example_subdag_operator.py
[2020-06-01 14:54:35,707] {scheduler_job.py:166} ERROR - Got an exception! Propagating...
Traceback (most recent call last):
  File "/usr/local/lib/python3.8/dist-packages/sqlalchemy/engine/base.py", line 774, in _commit_impl
    self.engine.dialect.do_commit(self.connection)
  File "/usr/local/lib/python3.8/dist-packages/sqlalchemy/engine/default.py", line 543, in do_commit
    dbapi_connection.commit()
sqlite3.OperationalError: disk I/O error

The above exception was the direct cause of the following exception:

Traceback (most recent call last):
  File "/usr/local/lib/python3.8/dist-packages/airflow/jobs/scheduler_job.py", line 156, in _run_file_processor
    result = scheduler_job.process_file(file_path,
  File "/usr/local/lib/python3.8/dist-packages/airflow/utils/db.py", line 74, in wrapper
    return func(*args, **kwargs)
  File "/usr/local/lib/python3.8/dist-packages/airflow/jobs/scheduler_job.py", line 1582, in process_file
    dag.sync_to_db()
  File "/usr/local/lib/python3.8/dist-packages/airflow/utils/db.py", line 74, in wrapper
    return func(*args, **kwargs)
  File "/usr/local/lib/python3.8/dist-packages/airflow/models/dag.py", line 1521, in sync_to_db
    session.commit()
  File "/usr/local/lib/python3.8/dist-packages/sqlalchemy/orm/session.py", line 1042, in commit
    self.transaction.commit()
  File "/usr/local/lib/python3.8/dist-packages/sqlalchemy/orm/session.py", line 508, in commit
    t[1].commit()
  File "/usr/local/lib/python3.8/dist-packages/sqlalchemy/engine/base.py", line 1771, in commit
    self._do_commit()
  File "/usr/local/lib/python3.8/dist-packages/sqlalchemy/engine/base.py", line 1802, in _do_commit
    self.connection._commit_impl()
  File "/usr/local/lib/python3.8/dist-packages/sqlalchemy/engine/base.py", line 776, in _commit_impl
    self._handle_dbapi_exception(e, None, None, None, None)
  File "/usr/local/lib/python3.8/dist-packages/sqlalchemy/engine/base.py", line 1517, in _handle_dbapi_exception
    util.raise_(
  File "/usr/local/lib/python3.8/dist-packages/sqlalchemy/util/compat.py", line 178, in raise_
    raise exception
  File "/usr/local/lib/python3.8/dist-packages/sqlalchemy/engine/base.py", line 774, in _commit_impl
    self.engine.dialect.do_commit(self.connection)
  File "/usr/local/lib/python3.8/dist-packages/sqlalchemy/engine/default.py", line 543, in do_commit
    dbapi_connection.commit()
sqlalchemy.exc.OperationalError: (sqlite3.OperationalError) disk I/O error
(Background on this error at: http://sqlalche.me/e/e3q8)
[2020-06-01 14:55:23,528] {scheduler_job.py:153} INFO - Started process (PID=641) to work on /usr/local/lib/python3.8/dist-packages/airflow/example_dags/example_subdag_operator.py
[2020-06-01 14:55:23,534] {scheduler_job.py:1562} INFO - Processing file /usr/local/lib/python3.8/dist-packages/airflow/example_dags/example_subdag_operator.py for tasks to queue
[2020-06-01 14:55:23,534] {logging_mixin.py:112} INFO - [2020-06-01 14:55:23,534] {dagbag.py:396} INFO - Filling up the DagBag from /usr/local/lib/python3.8/dist-packages/airflow/example_dags/example_subdag_operator.py
[2020-06-01 14:55:23,559] {scheduler_job.py:1574} INFO - DAG(s) dict_keys(['example_subdag_operator.section-1', 'example_subdag_operator.section-2', 'example_subdag_operator']) retrieved from /usr/local/lib/python3.8/dist-packages/airflow/example_dags/example_subdag_operator.py
[2020-06-01 14:55:23,806] {scheduler_job.py:166} ERROR - Got an exception! Propagating...
Traceback (most recent call last):
  File "/usr/local/lib/python3.8/dist-packages/sqlalchemy/engine/base.py", line 774, in _commit_impl
    self.engine.dialect.do_commit(self.connection)
  File "/usr/local/lib/python3.8/dist-packages/sqlalchemy/engine/default.py", line 543, in do_commit
    dbapi_connection.commit()
sqlite3.OperationalError: disk I/O error

The above exception was the direct cause of the following exception:

Traceback (most recent call last):
  File "/usr/local/lib/python3.8/dist-packages/airflow/jobs/scheduler_job.py", line 156, in _run_file_processor
    result = scheduler_job.process_file(file_path,
  File "/usr/local/lib/python3.8/dist-packages/airflow/utils/db.py", line 74, in wrapper
    return func(*args, **kwargs)
  File "/usr/local/lib/python3.8/dist-packages/airflow/jobs/scheduler_job.py", line 1582, in process_file
    dag.sync_to_db()
  File "/usr/local/lib/python3.8/dist-packages/airflow/utils/db.py", line 74, in wrapper
    return func(*args, **kwargs)
  File "/usr/local/lib/python3.8/dist-packages/airflow/models/dag.py", line 1521, in sync_to_db
    session.commit()
  File "/usr/local/lib/python3.8/dist-packages/sqlalchemy/orm/session.py", line 1042, in commit
    self.transaction.commit()
  File "/usr/local/lib/python3.8/dist-packages/sqlalchemy/orm/session.py", line 508, in commit
    t[1].commit()
  File "/usr/local/lib/python3.8/dist-packages/sqlalchemy/engine/base.py", line 1771, in commit
    self._do_commit()
  File "/usr/local/lib/python3.8/dist-packages/sqlalchemy/engine/base.py", line 1802, in _do_commit
    self.connection._commit_impl()
  File "/usr/local/lib/python3.8/dist-packages/sqlalchemy/engine/base.py", line 776, in _commit_impl
    self._handle_dbapi_exception(e, None, None, None, None)
  File "/usr/local/lib/python3.8/dist-packages/sqlalchemy/engine/base.py", line 1517, in _handle_dbapi_exception
    util.raise_(
  File "/usr/local/lib/python3.8/dist-packages/sqlalchemy/util/compat.py", line 178, in raise_
    raise exception
  File "/usr/local/lib/python3.8/dist-packages/sqlalchemy/engine/base.py", line 774, in _commit_impl
    self.engine.dialect.do_commit(self.connection)
  File "/usr/local/lib/python3.8/dist-packages/sqlalchemy/engine/default.py", line 543, in do_commit
    dbapi_connection.commit()
sqlalchemy.exc.OperationalError: (sqlite3.OperationalError) disk I/O error
(Background on this error at: http://sqlalche.me/e/e3q8)
[2020-06-01 14:56:11,578] {scheduler_job.py:153} INFO - Started process (PID=673) to work on /usr/local/lib/python3.8/dist-packages/airflow/example_dags/example_subdag_operator.py
[2020-06-01 14:56:11,583] {scheduler_job.py:1562} INFO - Processing file /usr/local/lib/python3.8/dist-packages/airflow/example_dags/example_subdag_operator.py for tasks to queue
[2020-06-01 14:56:11,584] {logging_mixin.py:112} INFO - [2020-06-01 14:56:11,584] {dagbag.py:396} INFO - Filling up the DagBag from /usr/local/lib/python3.8/dist-packages/airflow/example_dags/example_subdag_operator.py
[2020-06-01 14:56:11,612] {scheduler_job.py:1574} INFO - DAG(s) dict_keys(['example_subdag_operator.section-1', 'example_subdag_operator.section-2', 'example_subdag_operator']) retrieved from /usr/local/lib/python3.8/dist-packages/airflow/example_dags/example_subdag_operator.py
[2020-06-01 14:56:11,739] {scheduler_job.py:166} ERROR - Got an exception! Propagating...
Traceback (most recent call last):
  File "/usr/local/lib/python3.8/dist-packages/sqlalchemy/engine/base.py", line 774, in _commit_impl
    self.engine.dialect.do_commit(self.connection)
  File "/usr/local/lib/python3.8/dist-packages/sqlalchemy/engine/default.py", line 543, in do_commit
    dbapi_connection.commit()
sqlite3.OperationalError: disk I/O error

The above exception was the direct cause of the following exception:

Traceback (most recent call last):
  File "/usr/local/lib/python3.8/dist-packages/airflow/jobs/scheduler_job.py", line 156, in _run_file_processor
    result = scheduler_job.process_file(file_path,
  File "/usr/local/lib/python3.8/dist-packages/airflow/utils/db.py", line 74, in wrapper
    return func(*args, **kwargs)
  File "/usr/local/lib/python3.8/dist-packages/airflow/jobs/scheduler_job.py", line 1582, in process_file
    dag.sync_to_db()
  File "/usr/local/lib/python3.8/dist-packages/airflow/utils/db.py", line 74, in wrapper
    return func(*args, **kwargs)
  File "/usr/local/lib/python3.8/dist-packages/airflow/models/dag.py", line 1521, in sync_to_db
    session.commit()
  File "/usr/local/lib/python3.8/dist-packages/sqlalchemy/orm/session.py", line 1042, in commit
    self.transaction.commit()
  File "/usr/local/lib/python3.8/dist-packages/sqlalchemy/orm/session.py", line 508, in commit
    t[1].commit()
  File "/usr/local/lib/python3.8/dist-packages/sqlalchemy/engine/base.py", line 1771, in commit
    self._do_commit()
  File "/usr/local/lib/python3.8/dist-packages/sqlalchemy/engine/base.py", line 1802, in _do_commit
    self.connection._commit_impl()
  File "/usr/local/lib/python3.8/dist-packages/sqlalchemy/engine/base.py", line 776, in _commit_impl
    self._handle_dbapi_exception(e, None, None, None, None)
  File "/usr/local/lib/python3.8/dist-packages/sqlalchemy/engine/base.py", line 1517, in _handle_dbapi_exception
    util.raise_(
  File "/usr/local/lib/python3.8/dist-packages/sqlalchemy/util/compat.py", line 178, in raise_
    raise exception
  File "/usr/local/lib/python3.8/dist-packages/sqlalchemy/engine/base.py", line 774, in _commit_impl
    self.engine.dialect.do_commit(self.connection)
  File "/usr/local/lib/python3.8/dist-packages/sqlalchemy/engine/default.py", line 543, in do_commit
    dbapi_connection.commit()
sqlalchemy.exc.OperationalError: (sqlite3.OperationalError) disk I/O error
(Background on this error at: http://sqlalche.me/e/e3q8)
[2020-06-01 14:56:56,177] {scheduler_job.py:153} INFO - Started process (PID=716) to work on /usr/local/lib/python3.8/dist-packages/airflow/example_dags/example_subdag_operator.py
[2020-06-01 14:56:56,182] {scheduler_job.py:1562} INFO - Processing file /usr/local/lib/python3.8/dist-packages/airflow/example_dags/example_subdag_operator.py for tasks to queue
[2020-06-01 14:56:56,183] {logging_mixin.py:112} INFO - [2020-06-01 14:56:56,183] {dagbag.py:396} INFO - Filling up the DagBag from /usr/local/lib/python3.8/dist-packages/airflow/example_dags/example_subdag_operator.py
[2020-06-01 14:56:56,208] {scheduler_job.py:1574} INFO - DAG(s) dict_keys(['example_subdag_operator.section-1', 'example_subdag_operator.section-2', 'example_subdag_operator']) retrieved from /usr/local/lib/python3.8/dist-packages/airflow/example_dags/example_subdag_operator.py
[2020-06-01 14:56:56,740] {scheduler_job.py:161} INFO - Processing /usr/local/lib/python3.8/dist-packages/airflow/example_dags/example_subdag_operator.py took 0.563 seconds
[2020-06-01 14:57:44,219] {scheduler_job.py:153} INFO - Started process (PID=748) to work on /usr/local/lib/python3.8/dist-packages/airflow/example_dags/example_subdag_operator.py
[2020-06-01 14:57:44,224] {scheduler_job.py:1562} INFO - Processing file /usr/local/lib/python3.8/dist-packages/airflow/example_dags/example_subdag_operator.py for tasks to queue
[2020-06-01 14:57:44,224] {logging_mixin.py:112} INFO - [2020-06-01 14:57:44,224] {dagbag.py:396} INFO - Filling up the DagBag from /usr/local/lib/python3.8/dist-packages/airflow/example_dags/example_subdag_operator.py
[2020-06-01 14:57:44,256] {scheduler_job.py:1574} INFO - DAG(s) dict_keys(['example_subdag_operator.section-1', 'example_subdag_operator.section-2', 'example_subdag_operator']) retrieved from /usr/local/lib/python3.8/dist-packages/airflow/example_dags/example_subdag_operator.py
[2020-06-01 14:57:44,417] {scheduler_job.py:166} ERROR - Got an exception! Propagating...
Traceback (most recent call last):
  File "/usr/local/lib/python3.8/dist-packages/sqlalchemy/engine/base.py", line 774, in _commit_impl
    self.engine.dialect.do_commit(self.connection)
  File "/usr/local/lib/python3.8/dist-packages/sqlalchemy/engine/default.py", line 543, in do_commit
    dbapi_connection.commit()
sqlite3.OperationalError: disk I/O error

The above exception was the direct cause of the following exception:

Traceback (most recent call last):
  File "/usr/local/lib/python3.8/dist-packages/airflow/jobs/scheduler_job.py", line 156, in _run_file_processor
    result = scheduler_job.process_file(file_path,
  File "/usr/local/lib/python3.8/dist-packages/airflow/utils/db.py", line 74, in wrapper
    return func(*args, **kwargs)
  File "/usr/local/lib/python3.8/dist-packages/airflow/jobs/scheduler_job.py", line 1582, in process_file
    dag.sync_to_db()
  File "/usr/local/lib/python3.8/dist-packages/airflow/utils/db.py", line 74, in wrapper
    return func(*args, **kwargs)
  File "/usr/local/lib/python3.8/dist-packages/airflow/models/dag.py", line 1521, in sync_to_db
    session.commit()
  File "/usr/local/lib/python3.8/dist-packages/sqlalchemy/orm/session.py", line 1042, in commit
    self.transaction.commit()
  File "/usr/local/lib/python3.8/dist-packages/sqlalchemy/orm/session.py", line 508, in commit
    t[1].commit()
  File "/usr/local/lib/python3.8/dist-packages/sqlalchemy/engine/base.py", line 1771, in commit
    self._do_commit()
  File "/usr/local/lib/python3.8/dist-packages/sqlalchemy/engine/base.py", line 1802, in _do_commit
    self.connection._commit_impl()
  File "/usr/local/lib/python3.8/dist-packages/sqlalchemy/engine/base.py", line 776, in _commit_impl
    self._handle_dbapi_exception(e, None, None, None, None)
  File "/usr/local/lib/python3.8/dist-packages/sqlalchemy/engine/base.py", line 1517, in _handle_dbapi_exception
    util.raise_(
  File "/usr/local/lib/python3.8/dist-packages/sqlalchemy/util/compat.py", line 178, in raise_
    raise exception
  File "/usr/local/lib/python3.8/dist-packages/sqlalchemy/engine/base.py", line 774, in _commit_impl
    self.engine.dialect.do_commit(self.connection)
  File "/usr/local/lib/python3.8/dist-packages/sqlalchemy/engine/default.py", line 543, in do_commit
    dbapi_connection.commit()
sqlalchemy.exc.OperationalError: (sqlite3.OperationalError) disk I/O error
(Background on this error at: http://sqlalche.me/e/e3q8)
[2020-06-01 14:58:33,075] {scheduler_job.py:153} INFO - Started process (PID=776) to work on /usr/local/lib/python3.8/dist-packages/airflow/example_dags/example_subdag_operator.py
[2020-06-01 14:58:33,079] {scheduler_job.py:1562} INFO - Processing file /usr/local/lib/python3.8/dist-packages/airflow/example_dags/example_subdag_operator.py for tasks to queue
[2020-06-01 14:58:33,080] {logging_mixin.py:112} INFO - [2020-06-01 14:58:33,080] {dagbag.py:396} INFO - Filling up the DagBag from /usr/local/lib/python3.8/dist-packages/airflow/example_dags/example_subdag_operator.py
[2020-06-01 14:58:33,103] {scheduler_job.py:1574} INFO - DAG(s) dict_keys(['example_subdag_operator.section-1', 'example_subdag_operator.section-2', 'example_subdag_operator']) retrieved from /usr/local/lib/python3.8/dist-packages/airflow/example_dags/example_subdag_operator.py
[2020-06-01 14:58:33,317] {scheduler_job.py:166} ERROR - Got an exception! Propagating...
Traceback (most recent call last):
  File "/usr/local/lib/python3.8/dist-packages/sqlalchemy/engine/base.py", line 774, in _commit_impl
    self.engine.dialect.do_commit(self.connection)
  File "/usr/local/lib/python3.8/dist-packages/sqlalchemy/engine/default.py", line 543, in do_commit
    dbapi_connection.commit()
sqlite3.OperationalError: disk I/O error

The above exception was the direct cause of the following exception:

Traceback (most recent call last):
  File "/usr/local/lib/python3.8/dist-packages/airflow/jobs/scheduler_job.py", line 156, in _run_file_processor
    result = scheduler_job.process_file(file_path,
  File "/usr/local/lib/python3.8/dist-packages/airflow/utils/db.py", line 74, in wrapper
    return func(*args, **kwargs)
  File "/usr/local/lib/python3.8/dist-packages/airflow/jobs/scheduler_job.py", line 1582, in process_file
    dag.sync_to_db()
  File "/usr/local/lib/python3.8/dist-packages/airflow/utils/db.py", line 74, in wrapper
    return func(*args, **kwargs)
  File "/usr/local/lib/python3.8/dist-packages/airflow/models/dag.py", line 1521, in sync_to_db
    session.commit()
  File "/usr/local/lib/python3.8/dist-packages/sqlalchemy/orm/session.py", line 1042, in commit
    self.transaction.commit()
  File "/usr/local/lib/python3.8/dist-packages/sqlalchemy/orm/session.py", line 508, in commit
    t[1].commit()
  File "/usr/local/lib/python3.8/dist-packages/sqlalchemy/engine/base.py", line 1771, in commit
    self._do_commit()
  File "/usr/local/lib/python3.8/dist-packages/sqlalchemy/engine/base.py", line 1802, in _do_commit
    self.connection._commit_impl()
  File "/usr/local/lib/python3.8/dist-packages/sqlalchemy/engine/base.py", line 776, in _commit_impl
    self._handle_dbapi_exception(e, None, None, None, None)
  File "/usr/local/lib/python3.8/dist-packages/sqlalchemy/engine/base.py", line 1517, in _handle_dbapi_exception
    util.raise_(
  File "/usr/local/lib/python3.8/dist-packages/sqlalchemy/util/compat.py", line 178, in raise_
    raise exception
  File "/usr/local/lib/python3.8/dist-packages/sqlalchemy/engine/base.py", line 774, in _commit_impl
    self.engine.dialect.do_commit(self.connection)
  File "/usr/local/lib/python3.8/dist-packages/sqlalchemy/engine/default.py", line 543, in do_commit
    dbapi_connection.commit()
sqlalchemy.exc.OperationalError: (sqlite3.OperationalError) disk I/O error
(Background on this error at: http://sqlalche.me/e/e3q8)
[2020-06-01 14:59:21,142] {scheduler_job.py:153} INFO - Started process (PID=808) to work on /usr/local/lib/python3.8/dist-packages/airflow/example_dags/example_subdag_operator.py
[2020-06-01 14:59:21,147] {scheduler_job.py:1562} INFO - Processing file /usr/local/lib/python3.8/dist-packages/airflow/example_dags/example_subdag_operator.py for tasks to queue
[2020-06-01 14:59:21,148] {logging_mixin.py:112} INFO - [2020-06-01 14:59:21,148] {dagbag.py:396} INFO - Filling up the DagBag from /usr/local/lib/python3.8/dist-packages/airflow/example_dags/example_subdag_operator.py
[2020-06-01 14:59:21,176] {scheduler_job.py:1574} INFO - DAG(s) dict_keys(['example_subdag_operator.section-1', 'example_subdag_operator.section-2', 'example_subdag_operator']) retrieved from /usr/local/lib/python3.8/dist-packages/airflow/example_dags/example_subdag_operator.py
[2020-06-01 14:59:21,349] {scheduler_job.py:166} ERROR - Got an exception! Propagating...
Traceback (most recent call last):
  File "/usr/local/lib/python3.8/dist-packages/sqlalchemy/engine/base.py", line 774, in _commit_impl
    self.engine.dialect.do_commit(self.connection)
  File "/usr/local/lib/python3.8/dist-packages/sqlalchemy/engine/default.py", line 543, in do_commit
    dbapi_connection.commit()
sqlite3.OperationalError: disk I/O error

The above exception was the direct cause of the following exception:

Traceback (most recent call last):
  File "/usr/local/lib/python3.8/dist-packages/airflow/jobs/scheduler_job.py", line 156, in _run_file_processor
    result = scheduler_job.process_file(file_path,
  File "/usr/local/lib/python3.8/dist-packages/airflow/utils/db.py", line 74, in wrapper
    return func(*args, **kwargs)
  File "/usr/local/lib/python3.8/dist-packages/airflow/jobs/scheduler_job.py", line 1582, in process_file
    dag.sync_to_db()
  File "/usr/local/lib/python3.8/dist-packages/airflow/utils/db.py", line 74, in wrapper
    return func(*args, **kwargs)
  File "/usr/local/lib/python3.8/dist-packages/airflow/models/dag.py", line 1521, in sync_to_db
    session.commit()
  File "/usr/local/lib/python3.8/dist-packages/sqlalchemy/orm/session.py", line 1042, in commit
    self.transaction.commit()
  File "/usr/local/lib/python3.8/dist-packages/sqlalchemy/orm/session.py", line 508, in commit
    t[1].commit()
  File "/usr/local/lib/python3.8/dist-packages/sqlalchemy/engine/base.py", line 1771, in commit
    self._do_commit()
  File "/usr/local/lib/python3.8/dist-packages/sqlalchemy/engine/base.py", line 1802, in _do_commit
    self.connection._commit_impl()
  File "/usr/local/lib/python3.8/dist-packages/sqlalchemy/engine/base.py", line 776, in _commit_impl
    self._handle_dbapi_exception(e, None, None, None, None)
  File "/usr/local/lib/python3.8/dist-packages/sqlalchemy/engine/base.py", line 1517, in _handle_dbapi_exception
    util.raise_(
  File "/usr/local/lib/python3.8/dist-packages/sqlalchemy/util/compat.py", line 178, in raise_
    raise exception
  File "/usr/local/lib/python3.8/dist-packages/sqlalchemy/engine/base.py", line 774, in _commit_impl
    self.engine.dialect.do_commit(self.connection)
  File "/usr/local/lib/python3.8/dist-packages/sqlalchemy/engine/default.py", line 543, in do_commit
    dbapi_connection.commit()
sqlalchemy.exc.OperationalError: (sqlite3.OperationalError) disk I/O error
(Background on this error at: http://sqlalche.me/e/e3q8)
[2020-06-01 15:00:09,203] {scheduler_job.py:153} INFO - Started process (PID=836) to work on /usr/local/lib/python3.8/dist-packages/airflow/example_dags/example_subdag_operator.py
[2020-06-01 15:00:09,208] {scheduler_job.py:1562} INFO - Processing file /usr/local/lib/python3.8/dist-packages/airflow/example_dags/example_subdag_operator.py for tasks to queue
[2020-06-01 15:00:09,209] {logging_mixin.py:112} INFO - [2020-06-01 15:00:09,209] {dagbag.py:396} INFO - Filling up the DagBag from /usr/local/lib/python3.8/dist-packages/airflow/example_dags/example_subdag_operator.py
[2020-06-01 15:00:09,234] {scheduler_job.py:1574} INFO - DAG(s) dict_keys(['example_subdag_operator.section-1', 'example_subdag_operator.section-2', 'example_subdag_operator']) retrieved from /usr/local/lib/python3.8/dist-packages/airflow/example_dags/example_subdag_operator.py
[2020-06-01 15:00:09,449] {scheduler_job.py:166} ERROR - Got an exception! Propagating...
Traceback (most recent call last):
  File "/usr/local/lib/python3.8/dist-packages/sqlalchemy/engine/base.py", line 774, in _commit_impl
    self.engine.dialect.do_commit(self.connection)
  File "/usr/local/lib/python3.8/dist-packages/sqlalchemy/engine/default.py", line 543, in do_commit
    dbapi_connection.commit()
sqlite3.OperationalError: disk I/O error

The above exception was the direct cause of the following exception:

Traceback (most recent call last):
  File "/usr/local/lib/python3.8/dist-packages/airflow/jobs/scheduler_job.py", line 156, in _run_file_processor
    result = scheduler_job.process_file(file_path,
  File "/usr/local/lib/python3.8/dist-packages/airflow/utils/db.py", line 74, in wrapper
    return func(*args, **kwargs)
  File "/usr/local/lib/python3.8/dist-packages/airflow/jobs/scheduler_job.py", line 1582, in process_file
    dag.sync_to_db()
  File "/usr/local/lib/python3.8/dist-packages/airflow/utils/db.py", line 74, in wrapper
    return func(*args, **kwargs)
  File "/usr/local/lib/python3.8/dist-packages/airflow/models/dag.py", line 1521, in sync_to_db
    session.commit()
  File "/usr/local/lib/python3.8/dist-packages/sqlalchemy/orm/session.py", line 1042, in commit
    self.transaction.commit()
  File "/usr/local/lib/python3.8/dist-packages/sqlalchemy/orm/session.py", line 508, in commit
    t[1].commit()
  File "/usr/local/lib/python3.8/dist-packages/sqlalchemy/engine/base.py", line 1771, in commit
    self._do_commit()
  File "/usr/local/lib/python3.8/dist-packages/sqlalchemy/engine/base.py", line 1802, in _do_commit
    self.connection._commit_impl()
  File "/usr/local/lib/python3.8/dist-packages/sqlalchemy/engine/base.py", line 776, in _commit_impl
    self._handle_dbapi_exception(e, None, None, None, None)
  File "/usr/local/lib/python3.8/dist-packages/sqlalchemy/engine/base.py", line 1517, in _handle_dbapi_exception
    util.raise_(
  File "/usr/local/lib/python3.8/dist-packages/sqlalchemy/util/compat.py", line 178, in raise_
    raise exception
  File "/usr/local/lib/python3.8/dist-packages/sqlalchemy/engine/base.py", line 774, in _commit_impl
    self.engine.dialect.do_commit(self.connection)
  File "/usr/local/lib/python3.8/dist-packages/sqlalchemy/engine/default.py", line 543, in do_commit
    dbapi_connection.commit()
sqlalchemy.exc.OperationalError: (sqlite3.OperationalError) disk I/O error
(Background on this error at: http://sqlalche.me/e/e3q8)
[2020-06-01 15:00:57,251] {scheduler_job.py:153} INFO - Started process (PID=868) to work on /usr/local/lib/python3.8/dist-packages/airflow/example_dags/example_subdag_operator.py
[2020-06-01 15:00:57,256] {scheduler_job.py:1562} INFO - Processing file /usr/local/lib/python3.8/dist-packages/airflow/example_dags/example_subdag_operator.py for tasks to queue
[2020-06-01 15:00:57,257] {logging_mixin.py:112} INFO - [2020-06-01 15:00:57,257] {dagbag.py:396} INFO - Filling up the DagBag from /usr/local/lib/python3.8/dist-packages/airflow/example_dags/example_subdag_operator.py
[2020-06-01 15:00:57,282] {scheduler_job.py:1574} INFO - DAG(s) dict_keys(['example_subdag_operator.section-1', 'example_subdag_operator.section-2', 'example_subdag_operator']) retrieved from /usr/local/lib/python3.8/dist-packages/airflow/example_dags/example_subdag_operator.py
[2020-06-01 15:00:57,449] {scheduler_job.py:166} ERROR - Got an exception! Propagating...
Traceback (most recent call last):
  File "/usr/local/lib/python3.8/dist-packages/sqlalchemy/engine/base.py", line 774, in _commit_impl
    self.engine.dialect.do_commit(self.connection)
  File "/usr/local/lib/python3.8/dist-packages/sqlalchemy/engine/default.py", line 543, in do_commit
    dbapi_connection.commit()
sqlite3.OperationalError: disk I/O error

The above exception was the direct cause of the following exception:

Traceback (most recent call last):
  File "/usr/local/lib/python3.8/dist-packages/airflow/jobs/scheduler_job.py", line 156, in _run_file_processor
    result = scheduler_job.process_file(file_path,
  File "/usr/local/lib/python3.8/dist-packages/airflow/utils/db.py", line 74, in wrapper
    return func(*args, **kwargs)
  File "/usr/local/lib/python3.8/dist-packages/airflow/jobs/scheduler_job.py", line 1582, in process_file
    dag.sync_to_db()
  File "/usr/local/lib/python3.8/dist-packages/airflow/utils/db.py", line 74, in wrapper
    return func(*args, **kwargs)
  File "/usr/local/lib/python3.8/dist-packages/airflow/models/dag.py", line 1521, in sync_to_db
    session.commit()
  File "/usr/local/lib/python3.8/dist-packages/sqlalchemy/orm/session.py", line 1042, in commit
    self.transaction.commit()
  File "/usr/local/lib/python3.8/dist-packages/sqlalchemy/orm/session.py", line 508, in commit
    t[1].commit()
  File "/usr/local/lib/python3.8/dist-packages/sqlalchemy/engine/base.py", line 1771, in commit
    self._do_commit()
  File "/usr/local/lib/python3.8/dist-packages/sqlalchemy/engine/base.py", line 1802, in _do_commit
    self.connection._commit_impl()
  File "/usr/local/lib/python3.8/dist-packages/sqlalchemy/engine/base.py", line 776, in _commit_impl
    self._handle_dbapi_exception(e, None, None, None, None)
  File "/usr/local/lib/python3.8/dist-packages/sqlalchemy/engine/base.py", line 1517, in _handle_dbapi_exception
    util.raise_(
  File "/usr/local/lib/python3.8/dist-packages/sqlalchemy/util/compat.py", line 178, in raise_
    raise exception
  File "/usr/local/lib/python3.8/dist-packages/sqlalchemy/engine/base.py", line 774, in _commit_impl
    self.engine.dialect.do_commit(self.connection)
  File "/usr/local/lib/python3.8/dist-packages/sqlalchemy/engine/default.py", line 543, in do_commit
    dbapi_connection.commit()
sqlalchemy.exc.OperationalError: (sqlite3.OperationalError) disk I/O error
(Background on this error at: http://sqlalche.me/e/e3q8)
[2020-06-01 15:01:45,308] {scheduler_job.py:153} INFO - Started process (PID=896) to work on /usr/local/lib/python3.8/dist-packages/airflow/example_dags/example_subdag_operator.py
[2020-06-01 15:01:45,315] {scheduler_job.py:1562} INFO - Processing file /usr/local/lib/python3.8/dist-packages/airflow/example_dags/example_subdag_operator.py for tasks to queue
[2020-06-01 15:01:45,316] {logging_mixin.py:112} INFO - [2020-06-01 15:01:45,316] {dagbag.py:396} INFO - Filling up the DagBag from /usr/local/lib/python3.8/dist-packages/airflow/example_dags/example_subdag_operator.py
[2020-06-01 15:01:45,340] {scheduler_job.py:1574} INFO - DAG(s) dict_keys(['example_subdag_operator.section-1', 'example_subdag_operator.section-2', 'example_subdag_operator']) retrieved from /usr/local/lib/python3.8/dist-packages/airflow/example_dags/example_subdag_operator.py
[2020-06-01 15:01:45,516] {scheduler_job.py:166} ERROR - Got an exception! Propagating...
Traceback (most recent call last):
  File "/usr/local/lib/python3.8/dist-packages/sqlalchemy/engine/base.py", line 774, in _commit_impl
    self.engine.dialect.do_commit(self.connection)
  File "/usr/local/lib/python3.8/dist-packages/sqlalchemy/engine/default.py", line 543, in do_commit
    dbapi_connection.commit()
sqlite3.OperationalError: disk I/O error

The above exception was the direct cause of the following exception:

Traceback (most recent call last):
  File "/usr/local/lib/python3.8/dist-packages/airflow/jobs/scheduler_job.py", line 156, in _run_file_processor
    result = scheduler_job.process_file(file_path,
  File "/usr/local/lib/python3.8/dist-packages/airflow/utils/db.py", line 74, in wrapper
    return func(*args, **kwargs)
  File "/usr/local/lib/python3.8/dist-packages/airflow/jobs/scheduler_job.py", line 1582, in process_file
    dag.sync_to_db()
  File "/usr/local/lib/python3.8/dist-packages/airflow/utils/db.py", line 74, in wrapper
    return func(*args, **kwargs)
  File "/usr/local/lib/python3.8/dist-packages/airflow/models/dag.py", line 1521, in sync_to_db
    session.commit()
  File "/usr/local/lib/python3.8/dist-packages/sqlalchemy/orm/session.py", line 1042, in commit
    self.transaction.commit()
  File "/usr/local/lib/python3.8/dist-packages/sqlalchemy/orm/session.py", line 508, in commit
    t[1].commit()
  File "/usr/local/lib/python3.8/dist-packages/sqlalchemy/engine/base.py", line 1771, in commit
    self._do_commit()
  File "/usr/local/lib/python3.8/dist-packages/sqlalchemy/engine/base.py", line 1802, in _do_commit
    self.connection._commit_impl()
  File "/usr/local/lib/python3.8/dist-packages/sqlalchemy/engine/base.py", line 776, in _commit_impl
    self._handle_dbapi_exception(e, None, None, None, None)
  File "/usr/local/lib/python3.8/dist-packages/sqlalchemy/engine/base.py", line 1517, in _handle_dbapi_exception
    util.raise_(
  File "/usr/local/lib/python3.8/dist-packages/sqlalchemy/util/compat.py", line 178, in raise_
    raise exception
  File "/usr/local/lib/python3.8/dist-packages/sqlalchemy/engine/base.py", line 774, in _commit_impl
    self.engine.dialect.do_commit(self.connection)
  File "/usr/local/lib/python3.8/dist-packages/sqlalchemy/engine/default.py", line 543, in do_commit
    dbapi_connection.commit()
sqlalchemy.exc.OperationalError: (sqlite3.OperationalError) disk I/O error
(Background on this error at: http://sqlalche.me/e/e3q8)
[2020-06-01 15:02:33,374] {scheduler_job.py:153} INFO - Started process (PID=928) to work on /usr/local/lib/python3.8/dist-packages/airflow/example_dags/example_subdag_operator.py
[2020-06-01 15:02:33,379] {scheduler_job.py:1562} INFO - Processing file /usr/local/lib/python3.8/dist-packages/airflow/example_dags/example_subdag_operator.py for tasks to queue
[2020-06-01 15:02:33,380] {logging_mixin.py:112} INFO - [2020-06-01 15:02:33,380] {dagbag.py:396} INFO - Filling up the DagBag from /usr/local/lib/python3.8/dist-packages/airflow/example_dags/example_subdag_operator.py
[2020-06-01 15:02:33,415] {scheduler_job.py:1574} INFO - DAG(s) dict_keys(['example_subdag_operator.section-1', 'example_subdag_operator.section-2', 'example_subdag_operator']) retrieved from /usr/local/lib/python3.8/dist-packages/airflow/example_dags/example_subdag_operator.py
[2020-06-01 15:02:33,559] {scheduler_job.py:166} ERROR - Got an exception! Propagating...
Traceback (most recent call last):
  File "/usr/local/lib/python3.8/dist-packages/sqlalchemy/engine/base.py", line 774, in _commit_impl
    self.engine.dialect.do_commit(self.connection)
  File "/usr/local/lib/python3.8/dist-packages/sqlalchemy/engine/default.py", line 543, in do_commit
    dbapi_connection.commit()
sqlite3.OperationalError: disk I/O error

The above exception was the direct cause of the following exception:

Traceback (most recent call last):
  File "/usr/local/lib/python3.8/dist-packages/airflow/jobs/scheduler_job.py", line 156, in _run_file_processor
    result = scheduler_job.process_file(file_path,
  File "/usr/local/lib/python3.8/dist-packages/airflow/utils/db.py", line 74, in wrapper
    return func(*args, **kwargs)
  File "/usr/local/lib/python3.8/dist-packages/airflow/jobs/scheduler_job.py", line 1582, in process_file
    dag.sync_to_db()
  File "/usr/local/lib/python3.8/dist-packages/airflow/utils/db.py", line 74, in wrapper
    return func(*args, **kwargs)
  File "/usr/local/lib/python3.8/dist-packages/airflow/models/dag.py", line 1521, in sync_to_db
    session.commit()
  File "/usr/local/lib/python3.8/dist-packages/sqlalchemy/orm/session.py", line 1042, in commit
    self.transaction.commit()
  File "/usr/local/lib/python3.8/dist-packages/sqlalchemy/orm/session.py", line 508, in commit
    t[1].commit()
  File "/usr/local/lib/python3.8/dist-packages/sqlalchemy/engine/base.py", line 1771, in commit
    self._do_commit()
  File "/usr/local/lib/python3.8/dist-packages/sqlalchemy/engine/base.py", line 1802, in _do_commit
    self.connection._commit_impl()
  File "/usr/local/lib/python3.8/dist-packages/sqlalchemy/engine/base.py", line 776, in _commit_impl
    self._handle_dbapi_exception(e, None, None, None, None)
  File "/usr/local/lib/python3.8/dist-packages/sqlalchemy/engine/base.py", line 1517, in _handle_dbapi_exception
    util.raise_(
  File "/usr/local/lib/python3.8/dist-packages/sqlalchemy/util/compat.py", line 178, in raise_
    raise exception
  File "/usr/local/lib/python3.8/dist-packages/sqlalchemy/engine/base.py", line 774, in _commit_impl
    self.engine.dialect.do_commit(self.connection)
  File "/usr/local/lib/python3.8/dist-packages/sqlalchemy/engine/default.py", line 543, in do_commit
    dbapi_connection.commit()
sqlalchemy.exc.OperationalError: (sqlite3.OperationalError) disk I/O error
(Background on this error at: http://sqlalche.me/e/e3q8)
[2020-06-01 15:03:21,420] {scheduler_job.py:153} INFO - Started process (PID=956) to work on /usr/local/lib/python3.8/dist-packages/airflow/example_dags/example_subdag_operator.py
[2020-06-01 15:03:21,425] {scheduler_job.py:1562} INFO - Processing file /usr/local/lib/python3.8/dist-packages/airflow/example_dags/example_subdag_operator.py for tasks to queue
[2020-06-01 15:03:21,426] {logging_mixin.py:112} INFO - [2020-06-01 15:03:21,426] {dagbag.py:396} INFO - Filling up the DagBag from /usr/local/lib/python3.8/dist-packages/airflow/example_dags/example_subdag_operator.py
[2020-06-01 15:03:21,457] {scheduler_job.py:1574} INFO - DAG(s) dict_keys(['example_subdag_operator.section-1', 'example_subdag_operator.section-2', 'example_subdag_operator']) retrieved from /usr/local/lib/python3.8/dist-packages/airflow/example_dags/example_subdag_operator.py
[2020-06-01 15:03:21,593] {scheduler_job.py:166} ERROR - Got an exception! Propagating...
Traceback (most recent call last):
  File "/usr/local/lib/python3.8/dist-packages/sqlalchemy/engine/base.py", line 774, in _commit_impl
    self.engine.dialect.do_commit(self.connection)
  File "/usr/local/lib/python3.8/dist-packages/sqlalchemy/engine/default.py", line 543, in do_commit
    dbapi_connection.commit()
sqlite3.OperationalError: disk I/O error

The above exception was the direct cause of the following exception:

Traceback (most recent call last):
  File "/usr/local/lib/python3.8/dist-packages/airflow/jobs/scheduler_job.py", line 156, in _run_file_processor
    result = scheduler_job.process_file(file_path,
  File "/usr/local/lib/python3.8/dist-packages/airflow/utils/db.py", line 74, in wrapper
    return func(*args, **kwargs)
  File "/usr/local/lib/python3.8/dist-packages/airflow/jobs/scheduler_job.py", line 1582, in process_file
    dag.sync_to_db()
  File "/usr/local/lib/python3.8/dist-packages/airflow/utils/db.py", line 74, in wrapper
    return func(*args, **kwargs)
  File "/usr/local/lib/python3.8/dist-packages/airflow/models/dag.py", line 1521, in sync_to_db
    session.commit()
  File "/usr/local/lib/python3.8/dist-packages/sqlalchemy/orm/session.py", line 1042, in commit
    self.transaction.commit()
  File "/usr/local/lib/python3.8/dist-packages/sqlalchemy/orm/session.py", line 508, in commit
    t[1].commit()
  File "/usr/local/lib/python3.8/dist-packages/sqlalchemy/engine/base.py", line 1771, in commit
    self._do_commit()
  File "/usr/local/lib/python3.8/dist-packages/sqlalchemy/engine/base.py", line 1802, in _do_commit
    self.connection._commit_impl()
  File "/usr/local/lib/python3.8/dist-packages/sqlalchemy/engine/base.py", line 776, in _commit_impl
    self._handle_dbapi_exception(e, None, None, None, None)
  File "/usr/local/lib/python3.8/dist-packages/sqlalchemy/engine/base.py", line 1517, in _handle_dbapi_exception
    util.raise_(
  File "/usr/local/lib/python3.8/dist-packages/sqlalchemy/util/compat.py", line 178, in raise_
    raise exception
  File "/usr/local/lib/python3.8/dist-packages/sqlalchemy/engine/base.py", line 774, in _commit_impl
    self.engine.dialect.do_commit(self.connection)
  File "/usr/local/lib/python3.8/dist-packages/sqlalchemy/engine/default.py", line 543, in do_commit
    dbapi_connection.commit()
sqlalchemy.exc.OperationalError: (sqlite3.OperationalError) disk I/O error
(Background on this error at: http://sqlalche.me/e/e3q8)
