[2020-06-01 14:53:15,366] {scheduler_job.py:153} INFO - Started process (PID=542) to work on /usr/local/lib/python3.8/dist-packages/airflow/example_dags/example_complex.py
[2020-06-01 14:53:15,371] {scheduler_job.py:1562} INFO - Processing file /usr/local/lib/python3.8/dist-packages/airflow/example_dags/example_complex.py for tasks to queue
[2020-06-01 14:53:15,372] {logging_mixin.py:112} INFO - [2020-06-01 14:53:15,372] {dagbag.py:396} INFO - Filling up the DagBag from /usr/local/lib/python3.8/dist-packages/airflow/example_dags/example_complex.py
[2020-06-01 14:53:15,384] {scheduler_job.py:1574} INFO - DAG(s) dict_keys(['example_complex']) retrieved from /usr/local/lib/python3.8/dist-packages/airflow/example_dags/example_complex.py
[2020-06-01 14:53:15,492] {scheduler_job.py:161} INFO - Processing /usr/local/lib/python3.8/dist-packages/airflow/example_dags/example_complex.py took 0.126 seconds
[2020-06-01 14:54:03,469] {scheduler_job.py:153} INFO - Started process (PID=593) to work on /usr/local/lib/python3.8/dist-packages/airflow/example_dags/example_complex.py
[2020-06-01 14:54:03,474] {scheduler_job.py:1562} INFO - Processing file /usr/local/lib/python3.8/dist-packages/airflow/example_dags/example_complex.py for tasks to queue
[2020-06-01 14:54:03,475] {logging_mixin.py:112} INFO - [2020-06-01 14:54:03,475] {dagbag.py:396} INFO - Filling up the DagBag from /usr/local/lib/python3.8/dist-packages/airflow/example_dags/example_complex.py
[2020-06-01 14:54:03,488] {scheduler_job.py:1574} INFO - DAG(s) dict_keys(['example_complex']) retrieved from /usr/local/lib/python3.8/dist-packages/airflow/example_dags/example_complex.py
[2020-06-01 14:54:03,612] {scheduler_job.py:161} INFO - Processing /usr/local/lib/python3.8/dist-packages/airflow/example_dags/example_complex.py took 0.143 seconds
[2020-06-01 14:54:51,501] {scheduler_job.py:153} INFO - Started process (PID=621) to work on /usr/local/lib/python3.8/dist-packages/airflow/example_dags/example_complex.py
[2020-06-01 14:54:51,506] {scheduler_job.py:1562} INFO - Processing file /usr/local/lib/python3.8/dist-packages/airflow/example_dags/example_complex.py for tasks to queue
[2020-06-01 14:54:51,507] {logging_mixin.py:112} INFO - [2020-06-01 14:54:51,507] {dagbag.py:396} INFO - Filling up the DagBag from /usr/local/lib/python3.8/dist-packages/airflow/example_dags/example_complex.py
[2020-06-01 14:54:51,519] {scheduler_job.py:1574} INFO - DAG(s) dict_keys(['example_complex']) retrieved from /usr/local/lib/python3.8/dist-packages/airflow/example_dags/example_complex.py
[2020-06-01 14:54:51,679] {scheduler_job.py:161} INFO - Processing /usr/local/lib/python3.8/dist-packages/airflow/example_dags/example_complex.py took 0.178 seconds
[2020-06-01 14:55:39,555] {scheduler_job.py:153} INFO - Started process (PID=653) to work on /usr/local/lib/python3.8/dist-packages/airflow/example_dags/example_complex.py
[2020-06-01 14:55:39,560] {scheduler_job.py:1562} INFO - Processing file /usr/local/lib/python3.8/dist-packages/airflow/example_dags/example_complex.py for tasks to queue
[2020-06-01 14:55:39,561] {logging_mixin.py:112} INFO - [2020-06-01 14:55:39,561] {dagbag.py:396} INFO - Filling up the DagBag from /usr/local/lib/python3.8/dist-packages/airflow/example_dags/example_complex.py
[2020-06-01 14:55:39,573] {scheduler_job.py:1574} INFO - DAG(s) dict_keys(['example_complex']) retrieved from /usr/local/lib/python3.8/dist-packages/airflow/example_dags/example_complex.py
[2020-06-01 14:55:39,691] {scheduler_job.py:161} INFO - Processing /usr/local/lib/python3.8/dist-packages/airflow/example_dags/example_complex.py took 0.136 seconds
[2020-06-01 14:56:27,614] {scheduler_job.py:153} INFO - Started process (PID=681) to work on /usr/local/lib/python3.8/dist-packages/airflow/example_dags/example_complex.py
[2020-06-01 14:56:27,624] {scheduler_job.py:1562} INFO - Processing file /usr/local/lib/python3.8/dist-packages/airflow/example_dags/example_complex.py for tasks to queue
[2020-06-01 14:56:27,624] {logging_mixin.py:112} INFO - [2020-06-01 14:56:27,624] {dagbag.py:396} INFO - Filling up the DagBag from /usr/local/lib/python3.8/dist-packages/airflow/example_dags/example_complex.py
[2020-06-01 14:56:27,643] {scheduler_job.py:1574} INFO - DAG(s) dict_keys(['example_complex']) retrieved from /usr/local/lib/python3.8/dist-packages/airflow/example_dags/example_complex.py
[2020-06-01 14:56:27,782] {scheduler_job.py:161} INFO - Processing /usr/local/lib/python3.8/dist-packages/airflow/example_dags/example_complex.py took 0.168 seconds
[2020-06-01 14:57:08,190] {scheduler_job.py:153} INFO - Started process (PID=726) to work on /usr/local/lib/python3.8/dist-packages/airflow/example_dags/example_complex.py
[2020-06-01 14:57:08,196] {scheduler_job.py:1562} INFO - Processing file /usr/local/lib/python3.8/dist-packages/airflow/example_dags/example_complex.py for tasks to queue
[2020-06-01 14:57:08,196] {logging_mixin.py:112} INFO - [2020-06-01 14:57:08,196] {dagbag.py:396} INFO - Filling up the DagBag from /usr/local/lib/python3.8/dist-packages/airflow/example_dags/example_complex.py
[2020-06-01 14:57:08,211] {scheduler_job.py:1574} INFO - DAG(s) dict_keys(['example_complex']) retrieved from /usr/local/lib/python3.8/dist-packages/airflow/example_dags/example_complex.py
[2020-06-01 14:57:08,440] {scheduler_job.py:166} ERROR - Got an exception! Propagating...
Traceback (most recent call last):
  File "/usr/local/lib/python3.8/dist-packages/sqlalchemy/engine/base.py", line 774, in _commit_impl
    self.engine.dialect.do_commit(self.connection)
  File "/usr/local/lib/python3.8/dist-packages/sqlalchemy/engine/default.py", line 543, in do_commit
    dbapi_connection.commit()
sqlite3.OperationalError: disk I/O error

The above exception was the direct cause of the following exception:

Traceback (most recent call last):
  File "/usr/local/lib/python3.8/dist-packages/airflow/jobs/scheduler_job.py", line 156, in _run_file_processor
    result = scheduler_job.process_file(file_path,
  File "/usr/local/lib/python3.8/dist-packages/airflow/utils/db.py", line 74, in wrapper
    return func(*args, **kwargs)
  File "/usr/local/lib/python3.8/dist-packages/airflow/jobs/scheduler_job.py", line 1582, in process_file
    dag.sync_to_db()
  File "/usr/local/lib/python3.8/dist-packages/airflow/utils/db.py", line 74, in wrapper
    return func(*args, **kwargs)
  File "/usr/local/lib/python3.8/dist-packages/airflow/models/dag.py", line 1521, in sync_to_db
    session.commit()
  File "/usr/local/lib/python3.8/dist-packages/sqlalchemy/orm/session.py", line 1042, in commit
    self.transaction.commit()
  File "/usr/local/lib/python3.8/dist-packages/sqlalchemy/orm/session.py", line 508, in commit
    t[1].commit()
  File "/usr/local/lib/python3.8/dist-packages/sqlalchemy/engine/base.py", line 1771, in commit
    self._do_commit()
  File "/usr/local/lib/python3.8/dist-packages/sqlalchemy/engine/base.py", line 1802, in _do_commit
    self.connection._commit_impl()
  File "/usr/local/lib/python3.8/dist-packages/sqlalchemy/engine/base.py", line 776, in _commit_impl
    self._handle_dbapi_exception(e, None, None, None, None)
  File "/usr/local/lib/python3.8/dist-packages/sqlalchemy/engine/base.py", line 1517, in _handle_dbapi_exception
    util.raise_(
  File "/usr/local/lib/python3.8/dist-packages/sqlalchemy/util/compat.py", line 178, in raise_
    raise exception
  File "/usr/local/lib/python3.8/dist-packages/sqlalchemy/engine/base.py", line 774, in _commit_impl
    self.engine.dialect.do_commit(self.connection)
  File "/usr/local/lib/python3.8/dist-packages/sqlalchemy/engine/default.py", line 543, in do_commit
    dbapi_connection.commit()
sqlalchemy.exc.OperationalError: (sqlite3.OperationalError) disk I/O error
(Background on this error at: http://sqlalche.me/e/e3q8)
[2020-06-01 14:57:56,266] {scheduler_job.py:153} INFO - Started process (PID=754) to work on /usr/local/lib/python3.8/dist-packages/airflow/example_dags/example_complex.py
[2020-06-01 14:57:56,271] {scheduler_job.py:1562} INFO - Processing file /usr/local/lib/python3.8/dist-packages/airflow/example_dags/example_complex.py for tasks to queue
[2020-06-01 14:57:56,272] {logging_mixin.py:112} INFO - [2020-06-01 14:57:56,272] {dagbag.py:396} INFO - Filling up the DagBag from /usr/local/lib/python3.8/dist-packages/airflow/example_dags/example_complex.py
[2020-06-01 14:57:56,284] {scheduler_job.py:1574} INFO - DAG(s) dict_keys(['example_complex']) retrieved from /usr/local/lib/python3.8/dist-packages/airflow/example_dags/example_complex.py
[2020-06-01 14:57:56,423] {scheduler_job.py:161} INFO - Processing /usr/local/lib/python3.8/dist-packages/airflow/example_dags/example_complex.py took 0.157 seconds
[2020-06-01 14:58:45,080] {scheduler_job.py:153} INFO - Started process (PID=786) to work on /usr/local/lib/python3.8/dist-packages/airflow/example_dags/example_complex.py
[2020-06-01 14:58:45,085] {scheduler_job.py:1562} INFO - Processing file /usr/local/lib/python3.8/dist-packages/airflow/example_dags/example_complex.py for tasks to queue
[2020-06-01 14:58:45,086] {logging_mixin.py:112} INFO - [2020-06-01 14:58:45,086] {dagbag.py:396} INFO - Filling up the DagBag from /usr/local/lib/python3.8/dist-packages/airflow/example_dags/example_complex.py
[2020-06-01 14:58:45,098] {scheduler_job.py:1574} INFO - DAG(s) dict_keys(['example_complex']) retrieved from /usr/local/lib/python3.8/dist-packages/airflow/example_dags/example_complex.py
[2020-06-01 14:58:45,260] {scheduler_job.py:166} ERROR - Got an exception! Propagating...
Traceback (most recent call last):
  File "/usr/local/lib/python3.8/dist-packages/sqlalchemy/engine/base.py", line 774, in _commit_impl
    self.engine.dialect.do_commit(self.connection)
  File "/usr/local/lib/python3.8/dist-packages/sqlalchemy/engine/default.py", line 543, in do_commit
    dbapi_connection.commit()
sqlite3.OperationalError: disk I/O error

The above exception was the direct cause of the following exception:

Traceback (most recent call last):
  File "/usr/local/lib/python3.8/dist-packages/airflow/jobs/scheduler_job.py", line 156, in _run_file_processor
    result = scheduler_job.process_file(file_path,
  File "/usr/local/lib/python3.8/dist-packages/airflow/utils/db.py", line 74, in wrapper
    return func(*args, **kwargs)
  File "/usr/local/lib/python3.8/dist-packages/airflow/jobs/scheduler_job.py", line 1582, in process_file
    dag.sync_to_db()
  File "/usr/local/lib/python3.8/dist-packages/airflow/utils/db.py", line 74, in wrapper
    return func(*args, **kwargs)
  File "/usr/local/lib/python3.8/dist-packages/airflow/models/dag.py", line 1521, in sync_to_db
    session.commit()
  File "/usr/local/lib/python3.8/dist-packages/sqlalchemy/orm/session.py", line 1042, in commit
    self.transaction.commit()
  File "/usr/local/lib/python3.8/dist-packages/sqlalchemy/orm/session.py", line 508, in commit
    t[1].commit()
  File "/usr/local/lib/python3.8/dist-packages/sqlalchemy/engine/base.py", line 1771, in commit
    self._do_commit()
  File "/usr/local/lib/python3.8/dist-packages/sqlalchemy/engine/base.py", line 1802, in _do_commit
    self.connection._commit_impl()
  File "/usr/local/lib/python3.8/dist-packages/sqlalchemy/engine/base.py", line 776, in _commit_impl
    self._handle_dbapi_exception(e, None, None, None, None)
  File "/usr/local/lib/python3.8/dist-packages/sqlalchemy/engine/base.py", line 1517, in _handle_dbapi_exception
    util.raise_(
  File "/usr/local/lib/python3.8/dist-packages/sqlalchemy/util/compat.py", line 178, in raise_
    raise exception
  File "/usr/local/lib/python3.8/dist-packages/sqlalchemy/engine/base.py", line 774, in _commit_impl
    self.engine.dialect.do_commit(self.connection)
  File "/usr/local/lib/python3.8/dist-packages/sqlalchemy/engine/default.py", line 543, in do_commit
    dbapi_connection.commit()
sqlalchemy.exc.OperationalError: (sqlite3.OperationalError) disk I/O error
(Background on this error at: http://sqlalche.me/e/e3q8)
[2020-06-01 14:59:33,152] {scheduler_job.py:153} INFO - Started process (PID=814) to work on /usr/local/lib/python3.8/dist-packages/airflow/example_dags/example_complex.py
[2020-06-01 14:59:33,158] {scheduler_job.py:1562} INFO - Processing file /usr/local/lib/python3.8/dist-packages/airflow/example_dags/example_complex.py for tasks to queue
[2020-06-01 14:59:33,158] {logging_mixin.py:112} INFO - [2020-06-01 14:59:33,158] {dagbag.py:396} INFO - Filling up the DagBag from /usr/local/lib/python3.8/dist-packages/airflow/example_dags/example_complex.py
[2020-06-01 14:59:33,175] {scheduler_job.py:1574} INFO - DAG(s) dict_keys(['example_complex']) retrieved from /usr/local/lib/python3.8/dist-packages/airflow/example_dags/example_complex.py
[2020-06-01 14:59:33,327] {scheduler_job.py:161} INFO - Processing /usr/local/lib/python3.8/dist-packages/airflow/example_dags/example_complex.py took 0.174 seconds
[2020-06-01 15:00:21,219] {scheduler_job.py:153} INFO - Started process (PID=846) to work on /usr/local/lib/python3.8/dist-packages/airflow/example_dags/example_complex.py
[2020-06-01 15:00:21,224] {scheduler_job.py:1562} INFO - Processing file /usr/local/lib/python3.8/dist-packages/airflow/example_dags/example_complex.py for tasks to queue
[2020-06-01 15:00:21,225] {logging_mixin.py:112} INFO - [2020-06-01 15:00:21,225] {dagbag.py:396} INFO - Filling up the DagBag from /usr/local/lib/python3.8/dist-packages/airflow/example_dags/example_complex.py
[2020-06-01 15:00:21,239] {scheduler_job.py:1574} INFO - DAG(s) dict_keys(['example_complex']) retrieved from /usr/local/lib/python3.8/dist-packages/airflow/example_dags/example_complex.py
[2020-06-01 15:00:21,394] {scheduler_job.py:166} ERROR - Got an exception! Propagating...
Traceback (most recent call last):
  File "/usr/local/lib/python3.8/dist-packages/sqlalchemy/engine/base.py", line 774, in _commit_impl
    self.engine.dialect.do_commit(self.connection)
  File "/usr/local/lib/python3.8/dist-packages/sqlalchemy/engine/default.py", line 543, in do_commit
    dbapi_connection.commit()
sqlite3.OperationalError: disk I/O error

The above exception was the direct cause of the following exception:

Traceback (most recent call last):
  File "/usr/local/lib/python3.8/dist-packages/airflow/jobs/scheduler_job.py", line 156, in _run_file_processor
    result = scheduler_job.process_file(file_path,
  File "/usr/local/lib/python3.8/dist-packages/airflow/utils/db.py", line 74, in wrapper
    return func(*args, **kwargs)
  File "/usr/local/lib/python3.8/dist-packages/airflow/jobs/scheduler_job.py", line 1582, in process_file
    dag.sync_to_db()
  File "/usr/local/lib/python3.8/dist-packages/airflow/utils/db.py", line 74, in wrapper
    return func(*args, **kwargs)
  File "/usr/local/lib/python3.8/dist-packages/airflow/models/dag.py", line 1521, in sync_to_db
    session.commit()
  File "/usr/local/lib/python3.8/dist-packages/sqlalchemy/orm/session.py", line 1042, in commit
    self.transaction.commit()
  File "/usr/local/lib/python3.8/dist-packages/sqlalchemy/orm/session.py", line 508, in commit
    t[1].commit()
  File "/usr/local/lib/python3.8/dist-packages/sqlalchemy/engine/base.py", line 1771, in commit
    self._do_commit()
  File "/usr/local/lib/python3.8/dist-packages/sqlalchemy/engine/base.py", line 1802, in _do_commit
    self.connection._commit_impl()
  File "/usr/local/lib/python3.8/dist-packages/sqlalchemy/engine/base.py", line 776, in _commit_impl
    self._handle_dbapi_exception(e, None, None, None, None)
  File "/usr/local/lib/python3.8/dist-packages/sqlalchemy/engine/base.py", line 1517, in _handle_dbapi_exception
    util.raise_(
  File "/usr/local/lib/python3.8/dist-packages/sqlalchemy/util/compat.py", line 178, in raise_
    raise exception
  File "/usr/local/lib/python3.8/dist-packages/sqlalchemy/engine/base.py", line 774, in _commit_impl
    self.engine.dialect.do_commit(self.connection)
  File "/usr/local/lib/python3.8/dist-packages/sqlalchemy/engine/default.py", line 543, in do_commit
    dbapi_connection.commit()
sqlalchemy.exc.OperationalError: (sqlite3.OperationalError) disk I/O error
(Background on this error at: http://sqlalche.me/e/e3q8)
[2020-06-01 15:01:09,273] {scheduler_job.py:153} INFO - Started process (PID=874) to work on /usr/local/lib/python3.8/dist-packages/airflow/example_dags/example_complex.py
[2020-06-01 15:01:09,279] {scheduler_job.py:1562} INFO - Processing file /usr/local/lib/python3.8/dist-packages/airflow/example_dags/example_complex.py for tasks to queue
[2020-06-01 15:01:09,279] {logging_mixin.py:112} INFO - [2020-06-01 15:01:09,279] {dagbag.py:396} INFO - Filling up the DagBag from /usr/local/lib/python3.8/dist-packages/airflow/example_dags/example_complex.py
[2020-06-01 15:01:09,298] {scheduler_job.py:1574} INFO - DAG(s) dict_keys(['example_complex']) retrieved from /usr/local/lib/python3.8/dist-packages/airflow/example_dags/example_complex.py
[2020-06-01 15:01:09,694] {scheduler_job.py:166} ERROR - Got an exception! Propagating...
Traceback (most recent call last):
  File "/usr/local/lib/python3.8/dist-packages/sqlalchemy/engine/base.py", line 774, in _commit_impl
    self.engine.dialect.do_commit(self.connection)
  File "/usr/local/lib/python3.8/dist-packages/sqlalchemy/engine/default.py", line 543, in do_commit
    dbapi_connection.commit()
sqlite3.OperationalError: disk I/O error

The above exception was the direct cause of the following exception:

Traceback (most recent call last):
  File "/usr/local/lib/python3.8/dist-packages/airflow/jobs/scheduler_job.py", line 156, in _run_file_processor
    result = scheduler_job.process_file(file_path,
  File "/usr/local/lib/python3.8/dist-packages/airflow/utils/db.py", line 74, in wrapper
    return func(*args, **kwargs)
  File "/usr/local/lib/python3.8/dist-packages/airflow/jobs/scheduler_job.py", line 1582, in process_file
    dag.sync_to_db()
  File "/usr/local/lib/python3.8/dist-packages/airflow/utils/db.py", line 74, in wrapper
    return func(*args, **kwargs)
  File "/usr/local/lib/python3.8/dist-packages/airflow/models/dag.py", line 1521, in sync_to_db
    session.commit()
  File "/usr/local/lib/python3.8/dist-packages/sqlalchemy/orm/session.py", line 1042, in commit
    self.transaction.commit()
  File "/usr/local/lib/python3.8/dist-packages/sqlalchemy/orm/session.py", line 508, in commit
    t[1].commit()
  File "/usr/local/lib/python3.8/dist-packages/sqlalchemy/engine/base.py", line 1771, in commit
    self._do_commit()
  File "/usr/local/lib/python3.8/dist-packages/sqlalchemy/engine/base.py", line 1802, in _do_commit
    self.connection._commit_impl()
  File "/usr/local/lib/python3.8/dist-packages/sqlalchemy/engine/base.py", line 776, in _commit_impl
    self._handle_dbapi_exception(e, None, None, None, None)
  File "/usr/local/lib/python3.8/dist-packages/sqlalchemy/engine/base.py", line 1517, in _handle_dbapi_exception
    util.raise_(
  File "/usr/local/lib/python3.8/dist-packages/sqlalchemy/util/compat.py", line 178, in raise_
    raise exception
  File "/usr/local/lib/python3.8/dist-packages/sqlalchemy/engine/base.py", line 774, in _commit_impl
    self.engine.dialect.do_commit(self.connection)
  File "/usr/local/lib/python3.8/dist-packages/sqlalchemy/engine/default.py", line 543, in do_commit
    dbapi_connection.commit()
sqlalchemy.exc.OperationalError: (sqlite3.OperationalError) disk I/O error
(Background on this error at: http://sqlalche.me/e/e3q8)
[2020-06-01 15:01:57,352] {scheduler_job.py:153} INFO - Started process (PID=906) to work on /usr/local/lib/python3.8/dist-packages/airflow/example_dags/example_complex.py
[2020-06-01 15:01:57,357] {scheduler_job.py:1562} INFO - Processing file /usr/local/lib/python3.8/dist-packages/airflow/example_dags/example_complex.py for tasks to queue
[2020-06-01 15:01:57,358] {logging_mixin.py:112} INFO - [2020-06-01 15:01:57,358] {dagbag.py:396} INFO - Filling up the DagBag from /usr/local/lib/python3.8/dist-packages/airflow/example_dags/example_complex.py
[2020-06-01 15:01:57,375] {scheduler_job.py:1574} INFO - DAG(s) dict_keys(['example_complex']) retrieved from /usr/local/lib/python3.8/dist-packages/airflow/example_dags/example_complex.py
[2020-06-01 15:01:57,505] {scheduler_job.py:166} ERROR - Got an exception! Propagating...
Traceback (most recent call last):
  File "/usr/local/lib/python3.8/dist-packages/sqlalchemy/engine/base.py", line 774, in _commit_impl
    self.engine.dialect.do_commit(self.connection)
  File "/usr/local/lib/python3.8/dist-packages/sqlalchemy/engine/default.py", line 543, in do_commit
    dbapi_connection.commit()
sqlite3.OperationalError: disk I/O error

The above exception was the direct cause of the following exception:

Traceback (most recent call last):
  File "/usr/local/lib/python3.8/dist-packages/airflow/jobs/scheduler_job.py", line 156, in _run_file_processor
    result = scheduler_job.process_file(file_path,
  File "/usr/local/lib/python3.8/dist-packages/airflow/utils/db.py", line 74, in wrapper
    return func(*args, **kwargs)
  File "/usr/local/lib/python3.8/dist-packages/airflow/jobs/scheduler_job.py", line 1582, in process_file
    dag.sync_to_db()
  File "/usr/local/lib/python3.8/dist-packages/airflow/utils/db.py", line 74, in wrapper
    return func(*args, **kwargs)
  File "/usr/local/lib/python3.8/dist-packages/airflow/models/dag.py", line 1521, in sync_to_db
    session.commit()
  File "/usr/local/lib/python3.8/dist-packages/sqlalchemy/orm/session.py", line 1042, in commit
    self.transaction.commit()
  File "/usr/local/lib/python3.8/dist-packages/sqlalchemy/orm/session.py", line 508, in commit
    t[1].commit()
  File "/usr/local/lib/python3.8/dist-packages/sqlalchemy/engine/base.py", line 1771, in commit
    self._do_commit()
  File "/usr/local/lib/python3.8/dist-packages/sqlalchemy/engine/base.py", line 1802, in _do_commit
    self.connection._commit_impl()
  File "/usr/local/lib/python3.8/dist-packages/sqlalchemy/engine/base.py", line 776, in _commit_impl
    self._handle_dbapi_exception(e, None, None, None, None)
  File "/usr/local/lib/python3.8/dist-packages/sqlalchemy/engine/base.py", line 1517, in _handle_dbapi_exception
    util.raise_(
  File "/usr/local/lib/python3.8/dist-packages/sqlalchemy/util/compat.py", line 178, in raise_
    raise exception
  File "/usr/local/lib/python3.8/dist-packages/sqlalchemy/engine/base.py", line 774, in _commit_impl
    self.engine.dialect.do_commit(self.connection)
  File "/usr/local/lib/python3.8/dist-packages/sqlalchemy/engine/default.py", line 543, in do_commit
    dbapi_connection.commit()
sqlalchemy.exc.OperationalError: (sqlite3.OperationalError) disk I/O error
(Background on this error at: http://sqlalche.me/e/e3q8)
[2020-06-01 15:02:45,377] {scheduler_job.py:153} INFO - Started process (PID=934) to work on /usr/local/lib/python3.8/dist-packages/airflow/example_dags/example_complex.py
[2020-06-01 15:02:45,382] {scheduler_job.py:1562} INFO - Processing file /usr/local/lib/python3.8/dist-packages/airflow/example_dags/example_complex.py for tasks to queue
[2020-06-01 15:02:45,383] {logging_mixin.py:112} INFO - [2020-06-01 15:02:45,383] {dagbag.py:396} INFO - Filling up the DagBag from /usr/local/lib/python3.8/dist-packages/airflow/example_dags/example_complex.py
[2020-06-01 15:02:45,402] {scheduler_job.py:1574} INFO - DAG(s) dict_keys(['example_complex']) retrieved from /usr/local/lib/python3.8/dist-packages/airflow/example_dags/example_complex.py
[2020-06-01 15:02:45,548] {scheduler_job.py:166} ERROR - Got an exception! Propagating...
Traceback (most recent call last):
  File "/usr/local/lib/python3.8/dist-packages/sqlalchemy/engine/base.py", line 774, in _commit_impl
    self.engine.dialect.do_commit(self.connection)
  File "/usr/local/lib/python3.8/dist-packages/sqlalchemy/engine/default.py", line 543, in do_commit
    dbapi_connection.commit()
sqlite3.OperationalError: disk I/O error

The above exception was the direct cause of the following exception:

Traceback (most recent call last):
  File "/usr/local/lib/python3.8/dist-packages/airflow/jobs/scheduler_job.py", line 156, in _run_file_processor
    result = scheduler_job.process_file(file_path,
  File "/usr/local/lib/python3.8/dist-packages/airflow/utils/db.py", line 74, in wrapper
    return func(*args, **kwargs)
  File "/usr/local/lib/python3.8/dist-packages/airflow/jobs/scheduler_job.py", line 1582, in process_file
    dag.sync_to_db()
  File "/usr/local/lib/python3.8/dist-packages/airflow/utils/db.py", line 74, in wrapper
    return func(*args, **kwargs)
  File "/usr/local/lib/python3.8/dist-packages/airflow/models/dag.py", line 1521, in sync_to_db
    session.commit()
  File "/usr/local/lib/python3.8/dist-packages/sqlalchemy/orm/session.py", line 1042, in commit
    self.transaction.commit()
  File "/usr/local/lib/python3.8/dist-packages/sqlalchemy/orm/session.py", line 508, in commit
    t[1].commit()
  File "/usr/local/lib/python3.8/dist-packages/sqlalchemy/engine/base.py", line 1771, in commit
    self._do_commit()
  File "/usr/local/lib/python3.8/dist-packages/sqlalchemy/engine/base.py", line 1802, in _do_commit
    self.connection._commit_impl()
  File "/usr/local/lib/python3.8/dist-packages/sqlalchemy/engine/base.py", line 776, in _commit_impl
    self._handle_dbapi_exception(e, None, None, None, None)
  File "/usr/local/lib/python3.8/dist-packages/sqlalchemy/engine/base.py", line 1517, in _handle_dbapi_exception
    util.raise_(
  File "/usr/local/lib/python3.8/dist-packages/sqlalchemy/util/compat.py", line 178, in raise_
    raise exception
  File "/usr/local/lib/python3.8/dist-packages/sqlalchemy/engine/base.py", line 774, in _commit_impl
    self.engine.dialect.do_commit(self.connection)
  File "/usr/local/lib/python3.8/dist-packages/sqlalchemy/engine/default.py", line 543, in do_commit
    dbapi_connection.commit()
sqlalchemy.exc.OperationalError: (sqlite3.OperationalError) disk I/O error
(Background on this error at: http://sqlalche.me/e/e3q8)
[2020-06-01 15:03:33,424] {scheduler_job.py:153} INFO - Started process (PID=966) to work on /usr/local/lib/python3.8/dist-packages/airflow/example_dags/example_complex.py
[2020-06-01 15:03:33,430] {scheduler_job.py:1562} INFO - Processing file /usr/local/lib/python3.8/dist-packages/airflow/example_dags/example_complex.py for tasks to queue
[2020-06-01 15:03:33,430] {logging_mixin.py:112} INFO - [2020-06-01 15:03:33,430] {dagbag.py:396} INFO - Filling up the DagBag from /usr/local/lib/python3.8/dist-packages/airflow/example_dags/example_complex.py
[2020-06-01 15:03:33,448] {scheduler_job.py:1574} INFO - DAG(s) dict_keys(['example_complex']) retrieved from /usr/local/lib/python3.8/dist-packages/airflow/example_dags/example_complex.py
[2020-06-01 15:03:33,593] {scheduler_job.py:166} ERROR - Got an exception! Propagating...
Traceback (most recent call last):
  File "/usr/local/lib/python3.8/dist-packages/sqlalchemy/engine/base.py", line 774, in _commit_impl
    self.engine.dialect.do_commit(self.connection)
  File "/usr/local/lib/python3.8/dist-packages/sqlalchemy/engine/default.py", line 543, in do_commit
    dbapi_connection.commit()
sqlite3.OperationalError: disk I/O error

The above exception was the direct cause of the following exception:

Traceback (most recent call last):
  File "/usr/local/lib/python3.8/dist-packages/airflow/jobs/scheduler_job.py", line 156, in _run_file_processor
    result = scheduler_job.process_file(file_path,
  File "/usr/local/lib/python3.8/dist-packages/airflow/utils/db.py", line 74, in wrapper
    return func(*args, **kwargs)
  File "/usr/local/lib/python3.8/dist-packages/airflow/jobs/scheduler_job.py", line 1582, in process_file
    dag.sync_to_db()
  File "/usr/local/lib/python3.8/dist-packages/airflow/utils/db.py", line 74, in wrapper
    return func(*args, **kwargs)
  File "/usr/local/lib/python3.8/dist-packages/airflow/models/dag.py", line 1521, in sync_to_db
    session.commit()
  File "/usr/local/lib/python3.8/dist-packages/sqlalchemy/orm/session.py", line 1042, in commit
    self.transaction.commit()
  File "/usr/local/lib/python3.8/dist-packages/sqlalchemy/orm/session.py", line 508, in commit
    t[1].commit()
  File "/usr/local/lib/python3.8/dist-packages/sqlalchemy/engine/base.py", line 1771, in commit
    self._do_commit()
  File "/usr/local/lib/python3.8/dist-packages/sqlalchemy/engine/base.py", line 1802, in _do_commit
    self.connection._commit_impl()
  File "/usr/local/lib/python3.8/dist-packages/sqlalchemy/engine/base.py", line 776, in _commit_impl
    self._handle_dbapi_exception(e, None, None, None, None)
  File "/usr/local/lib/python3.8/dist-packages/sqlalchemy/engine/base.py", line 1517, in _handle_dbapi_exception
    util.raise_(
  File "/usr/local/lib/python3.8/dist-packages/sqlalchemy/util/compat.py", line 178, in raise_
    raise exception
  File "/usr/local/lib/python3.8/dist-packages/sqlalchemy/engine/base.py", line 774, in _commit_impl
    self.engine.dialect.do_commit(self.connection)
  File "/usr/local/lib/python3.8/dist-packages/sqlalchemy/engine/default.py", line 543, in do_commit
    dbapi_connection.commit()
sqlalchemy.exc.OperationalError: (sqlite3.OperationalError) disk I/O error
(Background on this error at: http://sqlalche.me/e/e3q8)
