[2020-06-02 15:31:34,908] {taskinstance.py:669} INFO - Dependencies all met for <TaskInstance: covid_tasks.get_covid_data_task 2020-06-02T09:56:02.150180+00:00 [queued]>
[2020-06-02 15:31:34,916] {taskinstance.py:669} INFO - Dependencies all met for <TaskInstance: covid_tasks.get_covid_data_task 2020-06-02T09:56:02.150180+00:00 [queued]>
[2020-06-02 15:31:34,916] {taskinstance.py:879} INFO - 
--------------------------------------------------------------------------------
[2020-06-02 15:31:34,916] {taskinstance.py:880} INFO - Starting attempt 2 of 2
[2020-06-02 15:31:34,916] {taskinstance.py:881} INFO - 
--------------------------------------------------------------------------------
[2020-06-02 15:31:35,117] {taskinstance.py:900} INFO - Executing <Task(PythonOperator): get_covid_data_task> on 2020-06-02T09:56:02.150180+00:00
[2020-06-02 15:31:35,140] {standard_task_runner.py:53} INFO - Started process 782 to run task
[2020-06-02 15:31:35,489] {logging_mixin.py:112} INFO - Running %s on host %s <TaskInstance: covid_tasks.get_covid_data_task 2020-06-02T09:56:02.150180+00:00 [running]> LAPTOP-P8ICNHVB.localdomain
[2020-06-02 15:31:37,220] {taskinstance.py:1145} ERROR - [Errno 2] No such file or directory: 'mnt/c/plugins/Output/CovidStats(2020-02-06).csv'
Traceback (most recent call last):
  File "/usr/local/lib/python3.8/dist-packages/airflow/models/taskinstance.py", line 983, in _run_raw_task
    result = task_copy.execute(context=context)
  File "/usr/local/lib/python3.8/dist-packages/airflow/operators/python_operator.py", line 113, in execute
    return_value = self.execute_callable()
  File "/usr/local/lib/python3.8/dist-packages/airflow/operators/python_operator.py", line 118, in execute_callable
    return self.python_callable(*self.op_args, **self.op_kwargs)
  File "/mnt/c/dag/covid_tasks.py", line 53, in get_statewise_data
    df.to_csv(f'mnt/c/plugins/Output/CovidStats({today}).csv', index=False)
  File "/usr/local/lib/python3.8/dist-packages/pandas/core/generic.py", line 3228, in to_csv
    formatter.save()
  File "/usr/local/lib/python3.8/dist-packages/pandas/io/formats/csvs.py", line 179, in save
    f, handles = _get_handle(
  File "/usr/local/lib/python3.8/dist-packages/pandas/io/common.py", line 399, in _get_handle
    f = open(path_or_buf, mode, encoding=encoding, newline="")
FileNotFoundError: [Errno 2] No such file or directory: 'mnt/c/plugins/Output/CovidStats(2020-02-06).csv'
[2020-06-02 15:31:37,226] {taskinstance.py:1174} INFO - All retries failed; marking task as FAILED.dag_id=covid_tasks, task_id=get_covid_data_task, execution_date=20200602T095602, start_date=20200602T100134, end_date=20200602T100137
[2020-06-02 15:31:44,840] {logging_mixin.py:112} INFO - [2020-06-02 15:31:44,840] {local_task_job.py:103} INFO - Task exited with return code 1
